Workbook

Sheet Daten
A1: Programm | B1: Universität gegründet (Jahr) | C1: Siege all-time (Siege) | D1: Siegquote all-time (%) | E1: Jahre seit letztem AP-Nationaltitel (Jahre) | F1: AP-Nationaltitel (Titel) | G1: Heisman-Sieger (Anzahl) | H1: Bowl-Siege all-time (Siege) | I1: CFP-Teilnahmen (Anzahl) | J1: Siege Saison 2025 (Siege) | K1: Stadionkapazität (Plätze) | L1: Stadion eröffnet (Jahr) | M1: Studierende (Tsd.) | N1: Einwohner Uni-Stadt (Tsd.) | O1: NFL-Draft-Picks 2026 (Spieler) | P1: Cheftrainer-Gehalt 2025 (Mio. USD) | Q1: Alumni auf NFL-Kadern Woche 1 2026 (Spieler) | R1: NFL-Draft-Picks seit 1980 (Spieler) | S1: Erstrunden-Picks seit 1980 (Spieler) | T1: Pro-Bowler gedraftet seit 1980 (Spieler) | U1: Hall-of-Famer gedraftet seit 1980 (Spieler) | V1: Combine-Teilnehmer seit 2000 (Spieler) | W1: Schnellster 40-Yard eines Alumni (Sekunden) | X1: HILFSSPALTE: Niederlagen all-time (Ende 2025) | Y1: HILFSSPALTE: Unentschieden all-time | Z1: HILFSSPALTE: Letzter AP-Titel (Saison) | AA1: HILFSSPALTE: Erste Football-Saison | AB1: HILFSSPALTE: Uni-Stadt | AC1: HILFSSPALTE: Head Coach Saison 2025 | AD1: HILFSSPALTE: Schulname in nflverse | AE1: Anmerkung
A2: Ohio State Buckeyes | B2: 1870 | C2: 990 | D2: =ROUND((C2+0.5*Y2)/(C2+X2+Y2),3) -> 0.737 | E2: =$B$35-IF(Z2="",AA2,Z2) -> 2 | F2: 6 | G2: 7 | H2: 30 | I2: 7 | J2: 12 | K2: 102780 | L2: 1922 | M2: 61.7 | N2: 913 | O2: 11 | P2: 12.575 | Q2: 56 | R2: 284 | S2: 69 | T2: 40 | U2: 1 | V2: 228 | W2: 4.27 | X2: 337 | Y2: 53 | Z2: 2024 | AA2: 1890 | AB2: Columbus, OH | AC2: Ryan Day | AD2: Ohio State | AE2: Beste Siegquote der FBS (.737). Nationaltitel 2024 (CFP). 11 Draft-Picks 2026 (Rekord der Liste, gleichauf mit Texas A&M).
A3: Alabama Crimson Tide | B3: 1831 | C3: 985 | D3: =ROUND((C3+0.5*Y3)/(C3+X3+Y3),3) -> 0.733 | E3: =$B$35-IF(Z3="",AA3,Z3) -> 6 | F3: 12 | G3: 4 | H3: 46 | I3: 8 | J3: 11 | K3: 100077 | L3: 1929 | M3: 40.8 | N3: 111 | O3: 10 | P3: 10.25 | Q3: 57 | R3: 263 | S3: 67 | T3: 39 | U3: 2 | V3: 222 | W3: 4.27 | X3: 345 | Y3: 43 | Z3: 2020 | AA3: 1892 | AB3: Tuscaloosa, AL | AC3: Kalen DeBoer | AD3: Alabama | AE3: Meiste AP-Titel (12) und meiste Bowl-Siege (46), meiste CFP-Teilnahmen (8).
A4: Notre Dame Fighting Irish | B4: 1842 | C4: 972 | D4: =ROUND((C4+0.5*Y4)/(C4+X4+Y4),3) -> 0.733 | E4: =$B$35-IF(Z4="",AA4,Z4) -> 38 | F4: 8 | G4: 7 | H4: 23 | I4: 3 | J4: 10 | K4: 77622 | L4: 1930 | M4: 13.2 | N4: 103 | O4: 5 | P4: 7.421 | Q4: 41 | R4: 241 | S4: 33 | T4: 31 | U4: 3 | V4: 168 | W4: 4.32 | X4: 341 | Y4: 42 | Z4: 1988 | AA4: 1887 | AB4: South Bend, IN | AC4: Marcus Freeman | AD4: Notre Dame | AE4: Independent (kein Conference-Football). Kleinste Uni der Liste. Jeremiyah Love = Nr.-3-Pick 2026.
A5: Michigan Wolverines | B5: 1817 | C5: 1021 | D5: =ROUND((C5+0.5*Y5)/(C5+X5+Y5),3) -> 0.732 | E5: =$B$35-IF(Z5="",AA5,Z5) -> 3 | F5: 3 | G5: 3 | H5: 24 | I5: 3 | J5: 9 | K5: 107601 | L5: 1927 | M5: 52.9 | N5: 122 | O5: 5 | P5: 6.11 | Q5: 40 | R5: 231 | S5: 37 | T5: 26 | U5: 3 | V5: 165 | W5: 4.26 | X5: 362 | Y5: 36 | Z5: 2023 | AA5: 1879 | AB5: Ann Arbor, MI | AC5: Sherrone Moore | AD5: Michigan | AE5: Meiste Siege der College-Geschichte (1'021) und grösstes Stadion der USA ('The Big House'). Älteste Uni der Liste (1817). Trainerwechsel 2026: Sherrone Moore → Kyle Whittingham (Gehaltswert = Saison 2025).
A6: Boise State Broncos | B6: 1932 | C6: 511 | D6: =ROUND((C6+0.5*Y6)/(C6+X6+Y6),3) -> 0.724 | E6: =$B$35-IF(Z6="",AA6,Z6) -> 58 | F6: 0 | G6: 0 | H6: 13 | I6: 1 | J6: 9 | K6: 36387 | L6: 1970 | M6: 25.8 | N6: 236 | O6: 1 | P6: 2.001 | Q6: 9 | R6: 59 | S6: 6 | T6: 6 | U6: 0 | V6: 63 | W6: 4.32 | X6: 194 | Y6: 2 | AA6: 1968 | AB6: Boise, ID | AC6: Spencer Danielson | AD6: Boise State | AE6: Blauer Kunstrasen. Nie AP-Titel: Durststrecke = seit Programmstart 1968. Kleinstes Stadion der Liste.
A7: Oklahoma Sooners | B7: 1890 | C7: 960 | D7: =ROUND((C7+0.5*Y7)/(C7+X7+Y7),3) -> 0.723 | E7: =$B$35-IF(Z7="",AA7,Z7) -> 26 | F7: 7 | G7: 7 | H7: 31 | I7: 5 | J7: 10 | K7: 80126 | L7: 1923 | M7: 32 | N7: 131 | O7: 5 | P7: 7.553 | Q7: 32 | R7: 224 | S7: 31 | T7: 24 | U7: 0 | V7: 170 | W7: 4.3 | X7: 351 | Y7: 53 | Z7: 2000 | AA7: 1895 | AB7: Norman, OK | AC7: Brent Venables | AD7: Oklahoma | AE7: 7 Heisman-Sieger (gleichauf mit Ohio State, Notre Dame). Seit 2024 in der SEC.
A8: Texas Longhorns | B8: 1883 | C8: 972 | D8: =ROUND((C8+0.5*Y8)/(C8+X8+Y8),3) -> 0.705 | E8: =$B$35-IF(Z8="",AA8,Z8) -> 21 | F8: 3 | G8: 2 | H8: 34 | I8: 2 | J8: 10 | K8: 100119 | L8: 1924 | M8: 53.1 | N8: 980 | O8: 6 | P8: 10.8 | Q8: 42 | R8: 206 | S8: 34 | T8: 22 | U8: 1 | V8: 146 | W8: 4.21 | X8: 397 | Y8: 33 | Z8: 2005 | AA8: 1893 | AB8: Austin, TX | AC8: Steve Sarkisian | AD8: Texas | AE8: Letzter AP-Titel 2005 (Vince Young). Seit 2024 in der SEC.
A9: USC Trojans | B9: 1880 | C9: 886 | D9: =ROUND((C9+0.5*Y9)/(C9+X9+Y9),3) -> 0.694 | E9: =$B$35-IF(Z9="",AA9,Z9) -> 22 | F9: 5 | G9: 8 | H9: 36 | I9: 0 | J9: 9 | K9: 77500 | L9: 1923 | M9: 49 | N9: 3821 | O9: 3 | P9: 11.538 | Q9: 27 | R9: 252 | S9: 56 | T9: 40 | U9: 7 | V9: 178 | W9: 4.31 | X9: 375 | Y9: 54 | Z9: 2004 | AA9: 1888 | AB9: Los Angeles, CA | AC9: Lincoln Riley | AD9: USC | AE9: Meiste Heisman-Sieger (8, inkl. Reggie Bush nach Wiedereinsetzung 2024). Grösste Stadt der Liste. Nie im CFP.
A10: Penn State Nittany Lions | B10: 1855 | C10: 946 | D10: =ROUND((C10+0.5*Y10)/(C10+X10+Y10),3) -> 0.691 | E10: =$B$35-IF(Z10="",AA10,Z10) -> 40 | F10: 2 | G10: 1 | H10: 34 | I10: 1 | J10: 7 | K10: 106304 | L10: 1960 | M10: 48.5 | N10: 40 | O10: 8 | P10: 8.5 | Q10: 36 | R10: 248 | S10: 36 | T10: 27 | U10: 1 | V10: 148 | W10: 4.31 | X10: 412 | Y10: 41 | Z10: 1986 | AA10: 1887 | AB10: State College, PA | AC10: James Franklin | AD10: Penn State | AE10: Beaver Stadium: zweitgrösstes Stadion (Kapazität während Umbau 2025/26 reduziert – vor Livegang prüfen). Kleinste Uni-Stadt (State College). Trainerwechsel 2026: James Franklin → Matt Campbell (Gehaltswert = Saison 2025).
A11: Nebraska Cornhuskers | B11: 1869 | C11: 927 | D11: =ROUND((C11+0.5*Y11)/(C11+X11+Y11),3) -> 0.678 | E11: =$B$35-IF(Z11="",AA11,Z11) -> 31 | F11: 4 | G11: 3 | H11: 27 | I11: 0 | J11: 7 | K11: 85458 | L11: 1923 | M11: 24 | N11: 295 | O11: 1 | P11: 8.5 | Q11: 7 | R11: 203 | S11: 20 | T11: 17 | U11: 2 | V11: 109 | W11: 4.29 | X11: 430 | Y11: 40 | Z11: 1995 | AA11: 1890 | AB11: Lincoln, NE | AC11: Matt Rhule | AD11: Nebraska | AE11: Ausverkauft seit 1962 (NCAA-Rekordserie). Letzter AP-Titel 1995.
A12: Tennessee Volunteers | B12: 1794 | C12: 877 | D12: =ROUND((C12+0.5*Y12)/(C12+X12+Y12),3) -> 0.67 | E12: =$B$35-IF(Z12="",AA12,Z12) -> 28 | F12: 2 | G12: 0 | H12: 31 | I12: 1 | J12: 8 | K12: 101915 | L12: 1921 | M12: 38.7 | N12: 198 | O12: 5 | P12: 9 | Q12: 21 | R12: 214 | S12: 38 | T12: 27 | U12: 1 | V12: 141 | W12: 4.22 | X12: 418 | Y12: 53 | Z12: 1998 | AA12: 1891 | AB12: Knoxville, TN | AC12: Josh Heupel | AD12: Tennessee | AE12: Zweitälteste Uni der Liste (1794). Neyland Stadium eröffnet 1921. Nie ein Heisman-Sieger.
A13: Georgia Bulldogs | B13: 1785 | C13: 895 | D13: =ROUND((C13+0.5*Y13)/(C13+X13+Y13),3) -> 0.668 | E13: =$B$35-IF(Z13="",AA13,Z13) -> 4 | F13: 3 | G13: 2 | H13: 38 | I13: 5 | J13: 12 | K13: 93033 | L13: 1929 | M13: 41.6 | N13: 129 | O13: 8 | P13: 13.283 | Q13: 52 | R13: 242 | S13: 45 | T13: 33 | U13: 3 | V13: 210 | W13: 4.31 | X13: 432 | Y13: 54 | Z13: 2022 | AA13: 1892 | AB13: Athens, GA | AC13: Kirby Smart | AD13: Georgia | AE13: Älteste staatliche Uni der USA (1785). AP-Titel 2021 und 2022. Meiste Unentschieden der Liste (54, mit USC).
A14: Florida State Seminoles | B14: 1851 | C14: 585 | D14: =ROUND((C14+0.5*Y14)/(C14+X14+Y14),3) -> 0.665 | E14: =$B$35-IF(Z14="",AA14,Z14) -> 13 | F14: 3 | G14: 3 | H14: 29 | I14: 1 | J14: 5 | K14: 79560 | L14: 1950 | M14: 44.2 | N14: 202 | O14: 1 | P14: 5.65 | Q14: 19 | R14: 227 | S14: 44 | T14: 34 | U14: 4 | V14: 176 | W14: 4.34 | X14: 291 | Y14: 17 | Z14: 2013 | AA14: 1947 | AB14: Tallahassee, FL | AC14: Mike Norvell | AD14: Florida State | AE14: Jüngstes Programm der Liste (1947). Drei Heisman-Sieger (Ward, Weinke, Winston). Norvell verzichtete 2025 freiwillig auf 4,5 Mio. (Wert nach Verzicht).
A15: LSU Tigers | B15: 1860 | C15: 818 | D15: =ROUND((C15+0.5*Y15)/(C15+X15+Y15),3) -> 0.646 | E15: =$B$35-IF(Z15="",AA15,Z15) -> 7 | F15: 3 | G15: 2 | H15: 31 | I15: 1 | J15: 7 | K15: 102321 | L15: 1924 | M15: 40 | N15: 220 | O15: 7 | P15: 10.175 | Q15: 44 | R15: 244 | S15: 38 | T15: 35 | U15: 2 | V15: 215 | W15: 4.28 | X15: 438 | Y15: 47 | Z15: 2019 | AA15: 1893 | AB15: Baton Rouge, LA | AC15: Brian Kelly | AD15: LSU | AE15: 'Death Valley'. AP-Titel 2019 (Joe Burrow, Heisman 2019). Trainerwechsel 2026: Brian Kelly → Lane Kiffin (Gehaltswert = Saison 2025).
A16: Miami Hurricanes | B16: 1925 | C16: 676 | D16: =ROUND((C16+0.5*Y16)/(C16+X16+Y16),3) -> 0.631 | E16: =$B$35-IF(Z16="",AA16,Z16) -> 25 | F16: 5 | G16: 2 | H16: 22 | I16: 1 | J16: 13 | K16: 65326 | L16: 1987 | M16: 19.6 | N16: 49 | O16: 9 | P16: 8.303 | Q16: 28 | R16: 265 | S16: 58 | T16: 45 | U16: 9 | V16: 143 | W16: 4.28 | X16: 391 | Y16: 19 | Z16: 2001 | AA16: 1926 | AB16: Coral Gables, FL | AC16: Mario Cristobal | AD16: Miami (FL) | AE16: CFP-Finalist 2025 (Niederlage gegen Indiana). Spielt im NFL-Stadion der Dolphins (Hard Rock Stadium, 1987). 9 Draft-Picks 2026.
A17: Florida Gators | B17: 1853 | C17: 767 | D17: =ROUND((C17+0.5*Y17)/(C17+X17+Y17),3) -> 0.625 | E17: =$B$35-IF(Z17="",AA17,Z17) -> 18 | F17: 3 | G17: 3 | H17: 26 | I17: 0 | J17: 4 | K17: 88548 | L17: 1930 | M17: 55.2 | N17: 145 | O17: 6 | P17: 7.47 | Q17: 37 | R17: 246 | S17: 50 | T17: 25 | U17: 1 | V17: 197 | W17: 4.32 | X17: 452 | Y17: 40 | Z17: 2008 | AA17: 1906 | AB17: Gainesville, FL | AC17: Billy Napier | AD17: Florida | AE17: 'The Swamp'. Drei Heisman-Sieger (Spurrier, Wuerffel, Tebow). Nie im CFP; nur 4 Siege 2025. Trainerwechsel 2026: Billy Napier → Jon Sumrall (Gehaltswert = Saison 2025).
A18: Clemson Tigers | B18: 1889 | C18: 809 | D18: =ROUND((C18+0.5*Y18)/(C18+X18+Y18),3) -> 0.624 | E18: =$B$35-IF(Z18="",AA18,Z18) -> 8 | F18: 3 | G18: 0 | H18: 27 | I18: 7 | J18: 7 | K18: 81500 | L18: 1942 | M18: 29 | N18: 17 | O18: 8 | P18: 11.447 | Q18: 30 | R18: 199 | S18: 35 | T18: 22 | U18: 1 | V18: 146 | W18: 4.28 | X18: 478 | Y18: 45 | Z18: 2018 | AA18: 1896 | AB18: Clemson, SC | AC18: Dabo Swinney | AD18: Clemson | AE18: 7 CFP-Teilnahmen (Nr. 2 der Liste). Kleinste Uni-Stadt der Liste (Clemson, ca. 17'000). Nie ein Heisman-Sieger.
A19: Auburn Tigers | B19: 1856 | C19: 807 | D19: =ROUND((C19+0.5*Y19)/(C19+X19+Y19),3) -> 0.623 | E19: =$B$35-IF(Z19="",AA19,Z19) -> 16 | F19: 2 | G19: 3 | H19: 24 | I19: 0 | J19: 5 | K19: 88043 | L19: 1939 | M19: 33 | N19: 81 | O19: 4 | P19: 6.735 | Q19: 23 | R19: 183 | S19: 22 | T19: 22 | U19: 1 | V19: 135 | W19: 4.27 | X19: 478 | Y19: 47 | Z19: 2010 | AA19: 1892 | AB19: Auburn, AL | AC19: Hugh Freeze | AD19: Auburn | AE19: Drei Heisman-Sieger (Sullivan, Bo Jackson, Cam Newton). Nie im CFP. Trainerwechsel 2026: Hugh Freeze → Alex Golesh (Gehaltswert = Saison 2025).
A20: Washington Huskies | B20: 1861 | C20: 783 | D20: =ROUND((C20+0.5*Y20)/(C20+X20+Y20),3) -> 0.618 | E20: =$B$35-IF(Z20="",AA20,Z20) -> 137 | F20: 0 | G20: 0 | H20: 21 | I20: 2 | J20: 9 | K20: 70138 | L20: 1920 | M20: 52.5 | N20: 755 | O20: 7 | P20: 7.575 | Q20: 23 | R20: 191 | S20: 26 | T20: 14 | U20: 0 | V20: 105 | W20: 4.22 | X20: 474 | Y20: 50 | AA20: 1889 | AB20: Seattle, WA | AC20: Jedd Fisch | AD20: Washington | AE20: Nie AP-Titel (Coaches-Poll 1991): Durststrecke = seit Programmstart 1889. CFP-Finalist 2023.
A21: Texas A&M Aggies | B21: 1876 | C21: 789 | D21: =ROUND((C21+0.5*Y21)/(C21+X21+Y21),3) -> 0.604 | E21: =$B$35-IF(Z21="",AA21,Z21) -> 87 | F21: 1 | G21: 2 | H21: 20 | I21: 1 | J21: 11 | K21: 102733 | L21: 1927 | M21: 79.1 | N21: 125 | O21: 11 | P21: 7 | Q21: 26 | R21: 193 | S21: 28 | T21: 19 | U21: 0 | V21: 133 | W21: 4.32 | X21: 509 | Y21: 48 | Z21: 1939 | AA21: 1894 | AB21: College Station, TX | AC21: Mike Elko | AD21: Texas A&M | AE21: Grösste Uni der Liste (ca. 79'000). Letzter AP-Titel 1939 – längste Durststrecke eines Ex-Meisters. 11 Draft-Picks 2026.
A22: Arizona State Sun Devils | B22: 1885 | C22: 641 | D22: =ROUND((C22+0.5*Y22)/(C22+X22+Y22),3) -> 0.597 | E22: =$B$35-IF(Z22="",AA22,Z22) -> 129 | F22: 0 | G22: 0 | H22: 15 | I22: 1 | J22: 8 | K22: 53599 | L22: 1958 | M22: 80.1 | N22: 189 | O22: 4 | P22: 7.442 | Q22: 6 | R22: 151 | S22: 18 | T22: 13 | U22: 2 | V22: 96 | W22: 4.32 | X22: 428 | Y22: 24 | AA22: 1897 | AB22: Tempe, AZ | AC22: Kenny Dillingham | AD22: Arizona State | AE22: Grösste Uni (Campus Tempe ca. 80'000 – Zählweise vor Livegang prüfen). Nie AP-Titel.
A23: Michigan State Spartans | B23: 1855 | C23: 738 | D23: =ROUND((C23+0.5*Y23)/(C23+X23+Y23),3) -> 0.596 | E23: =$B$35-IF(Z23="",AA23,Z23) -> 74 | F23: 1 | G23: 0 | H23: 14 | I23: 1 | J23: 4 | K23: 75005 | L23: 1923 | M23: 51.3 | N23: 47 | O23: 2 | P23: 7.35 | Q23: 13 | R23: 147 | S23: 17 | T23: 14 | U23: 1 | V23: 113 | W23: 4.31 | X23: 494 | Y23: 44 | Z23: 1952 | AA23: 1896 | AB23: East Lansing, MI | AC23: Jonathan Smith | AD23: Michigan State | AE23: Letzter AP-Titel 1952 (zweitlängste Durststrecke eines Ex-Meisters). Trainerwechsel 2026: Jonathan Smith → Pat Fitzgerald (Gehaltswert = Saison 2025).
A24: Utah Utes | B24: 1850 | C24: 727 | D24: =ROUND((C24+0.5*Y24)/(C24+X24+Y24),3) -> 0.595 | E24: =$B$35-IF(Z24="",AA24,Z24) -> 134 | F24: 0 | G24: 0 | H24: 18 | I24: 0 | J24: 11 | K24: 51444 | L24: 1998 | M24: 35 | N24: 210 | O24: 3 | P24: 6.925 | Q24: 22 | R24: 97 | S24: 10 | T24: 13 | U24: 0 | V24: 100 | W24: 4.29 | X24: 489 | Y24: 31 | AA24: 1892 | AB24: Salt Lake City, UT | AC24: Kyle Whittingham | AD24: Utah | AE24: Jüngstes Stadion der Liste (Rice-Eccles 1998). Nie AP-Titel, nie im CFP. 11 Siege 2025. Trainerwechsel 2026: Kyle Whittingham → Morgan Scalley (Gehaltswert = Saison 2025).
A25: Wisconsin Badgers | B25: 1848 | C25: 749 | D25: =ROUND((C25+0.5*Y25)/(C25+X25+Y25),3) -> 0.584 | E25: =$B$35-IF(Z25="",AA25,Z25) -> 137 | F25: 0 | G25: 2 | H25: 19 | I25: 0 | J25: 4 | K25: 76057 | L25: 1917 | M25: 51.7 | N25: 280 | O25: 0 | P25: 7.825 | Q25: 18 | R25: 164 | S25: 22 | T25: 20 | U25: 1 | V25: 132 | W25: 4.33 | X25: 526 | Y25: 53 | AA25: 1889 | AB25: Madison, WI | AC25: Luke Fickell | AD25: Wisconsin | AE25: Nie AP-Titel. Zwei Heisman-Sieger (Ameche, Dayne). Kein Draft-Pick 2026. Camp Randall: zweitältestes Stadion der Liste (1917).
A26: Oregon Ducks | B26: 1876 | C26: 721 | D26: =ROUND((C26+0.5*Y26)/(C26+X26+Y26),3) -> 0.582 | E26: =$B$35-IF(Z26="",AA26,Z26) -> 132 | F26: 0 | G26: 1 | H26: 19 | I26: 3 | J26: 13 | K26: 54000 | L26: 1967 | M26: 24 | N26: 178 | O26: 7 | P26: 10.4 | Q26: 36 | R26: 153 | S26: 20 | T26: 13 | U26: 0 | V26: 142 | W26: 4.35 | X26: 512 | Y26: 46 | AA26: 1894 | AB26: Eugene, OR | AC26: Dan Lanning | AD26: Oregon | AE26: Nie AP-Titel (CFP-Finalist 2014). 13 Siege 2025. Heisman: Mariota 2014.
A27: Colorado Buffaloes | B27: 1876 | C27: 733 | D27: =ROUND((C27+0.5*Y27)/(C27+X27+Y27),3) -> 0.569 | E27: =$B$35-IF(Z27="",AA27,Z27) -> 36 | F27: 1 | G27: 2 | H27: 12 | I27: 0 | J27: 3 | K27: 50183 | L27: 1924 | M27: 38 | N27: 105 | O27: 0 | P27: 8.975 | Q27: 9 | R27: 132 | S27: 16 | T27: 10 | U27: 0 | V27: 71 | W27: 4.37 | X27: 550 | Y27: 36 | Z27: 1990 | AA27: 1890 | AB27: Boulder, CO | AC27: Deion Sanders | AD27: Colorado | AE27: Heisman 2024 (Travis Hunter), Head Coach Deion Sanders. Nur 3 Siege 2025, kein Draft-Pick 2026.
A28: Ole Miss Rebels | B28: 1848 | C28: 688 | D28: =ROUND((C28+0.5*Y28)/(C28+X28+Y28),3) -> 0.554 | E28: =$B$35-IF(Z28="",AA28,Z28) -> 133 | F28: 0 | G28: 0 | H28: 28 | I28: 1 | J28: 13 | K28: 64038 | L28: 1915 | M28: 24.7 | N28: 28 | O28: 2 | P28: 9 | Q28: 26 | R28: 116 | S28: 17 | T28: 15 | U28: 1 | V28: 104 | W28: 4.29 | X28: 550 | Y28: 35 | AA28: 1893 | AB28: Oxford, MS | AC28: Lane Kiffin | AD28: Mississippi | AE28: Ältestes Stadion der Liste (Vaught-Hemingway 1915). 13 Siege 2025 (Programmrekord), erste CFP-Teilnahme. Nie AP-Titel. Trainerwechsel 2026: Lane Kiffin → Pete Golding (Gehaltswert = Saison 2025).
A29: Texas Tech Red Raiders | B29: 1923 | C29: 608 | D29: =ROUND((C29+0.5*Y29)/(C29+X29+Y29),3) -> 0.554 | E29: =$B$35-IF(Z29="",AA29,Z29) -> 101 | F29: 0 | G29: 0 | H29: 17 | I29: 1 | J29: 12 | K29: 60229 | L29: 1947 | M29: 41 | N29: 267 | O29: 8 | P29: 4.55 | Q29: 18 | R29: 89 | S29: 7 | T29: 4 | U29: 1 | V29: 69 | W29: 4.33 | X29: 486 | Y29: 32 | AA29: 1925 | AB29: Lubbock, TX | AC29: Joey McGuire | AD29: Texas Tech | AE29: Big-12-Champion 2025, erste CFP-Teilnahme. David Bailey = Nr.-2-Pick 2026. Nie AP-Titel. McGuire-Gehalt 2025 nur ausserhalb der USA-Today-Top-50 belegt (SI); ab 2026 6,5 Mio.
A30: Missouri Tigers | B30: 1839 | C30: 724 | D30: =ROUND((C30+0.5*Y30)/(C30+X30+Y30),3) -> 0.548 | E30: =$B$35-IF(Z30="",AA30,Z30) -> 136 | F30: 0 | G30: 0 | H30: 17 | I30: 0 | J30: 8 | K30: 62621 | L30: 1926 | M30: 32 | N30: 128 | O30: 6 | P30: 9 | Q30: 22 | R30: 108 | S30: 13 | T30: 11 | U30: 0 | V30: 88 | W30: 4.32 | X30: 593 | Y30: 52 | AA30: 1890 | AB30: Columbia, MO | AC30: Eli Drinkwitz | AD30: Missouri | AE30: Nie AP-Titel, nie im CFP. Seit 2012 in der SEC.
A31: Iowa Hawkeyes | B31: 1847 | C31: 703 | D31: =ROUND((C31+0.5*Y31)/(C31+X31+Y31),3) -> 0.546 | E31: =$B$35-IF(Z31="",AA31,Z31) -> 137 | F31: 0 | G31: 1 | H31: 19 | I31: 0 | J31: 9 | K31: 69250 | L31: 1929 | M31: 31.4 | N31: 75 | O31: 6 | P31: 7.175 | Q31: 31 | R31: 164 | S31: 20 | T31: 24 | U31: 1 | V31: 144 | W31: 4.35 | X31: 582 | Y31: 39 | AA31: 1889 | AB31: Iowa City, IA | AC31: Kirk Ferentz | AD31: Iowa | AE31: Heisman 1939 (Nile Kinnick, Stadion nach ihm benannt). Nie AP-Titel (Coaches-Poll 1958).
A32: TCU Horned Frogs | B32: 1873 | C32: 696 | D32: =ROUND((C32+0.5*Y32)/(C32+X32+Y32),3) -> 0.544 | E32: =$B$35-IF(Z32="",AA32,Z32) -> 88 | F32: 2 | G32: 1 | H32: 20 | I32: 1 | J32: 9 | K32: 45000 | L32: 1930 | M32: 13.1 | N32: 978 | O32: 1 | P32: 7.036 | Q32: 21 | R32: 103 | S32: 8 | T32: 7 | U32: 1 | V32: 97 | W32: 4.36 | X32: 578 | Y32: 57 | Z32: 1938 | AA32: 1896 | AB32: Fort Worth, TX | AC32: Sonny Dykes | AD32: TCU | AE32: Meiste Unentschieden der Liste (57). AP-Titel 1938 – längste Durststrecke aller Ex-Meister (88 Jahre). CFP-Finalist 2022.
A33: Indiana Hoosiers | B33: 1820 | C33: 521 | D33: =ROUND((C33+0.5*Y33)/(C33+X33+Y33),3) -> 0.424 | E33: =$B$35-IF(Z33="",AA33,Z33) -> 1 | F33: 1 | G33: 1 | H33: 6 | I33: 2 | J33: 16 | K33: 52626 | L33: 1960 | M33: 48.4 | N33: 80 | O33: 8 | P33: 8.3 | Q33: 18 | R33: 71 | S33: 6 | T33: 3 | U33: 0 | V33: 60 | W33: 4.36 | X33: 715 | Y33: 44 | Z33: 2025 | AA33: 1887 | AB33: Bloomington, IN | AC33: Curt Cignetti | AD33: Indiana | AE33: Nationalmeister 2025 (16-0, CFP-Finale gegen Miami), Heisman 2025 (Fernando Mendoza, Nr.-1-Pick 2026). Schlechteste All-time-Siegquote der Liste (.424), nur 6 Bowl-Siege.
A35: Referenzjahr / Stichtag (für Formeln) | B35: 2026
A36: Graue Spalten = Hilfsspalten (Rohdaten für Formeln), nicht als Attribut im Spiel verwenden. Formelspalten rechnen live aus den Hilfsspalten.
A37: Werte mit dem Vermerk 'vor Livegang prüfen' in der Anmerkung/Kategorien-Tabelle vor Veröffentlichung gegenprüfen.

Sheet Ränge
A1: Programm | B1: Universität gegründet | C1: Siege all-time | D1: Siegquote all-time | E1: Jahre seit letztem AP-Nationaltitel | F1: AP-Nationaltitel | G1: Heisman-Sieger | H1: Bowl-Siege all-time | I1: CFP-Teilnahmen | J1: Siege Saison 2025 | K1: Stadionkapazität | L1: Stadion eröffnet | M1: Studierende | N1: Einwohner Uni-Stadt | O1: NFL-Draft-Picks 2026 | P1: Cheftrainer-Gehalt 2025 | Q1: Alumni auf NFL-Kadern Woche 1 2026 | R1: NFL-Draft-Picks seit 1980 | S1: Erstrunden-Picks seit 1980 | T1: Pro-Bowler gedraftet seit 1980 | U1: Hall-of-Famer gedraftet seit 1980 | V1: Combine-Teilnehmer seit 2000 | W1: Schnellster 40-Yard eines Alumni | X1: Anzahl Top-3-Ränge | Y1: Anzahl Rang 1
A2: =Daten!A2 -> Ohio State Buckeyes | B2: =RANK(Daten!B2,Daten!B$2:B$33,1) -> 20 | C2: =RANK(Daten!C2,Daten!C$2:C$33,0) -> 2 | D2: =RANK(Daten!D2,Daten!D$2:D$33,0) -> 1 | E2: =RANK(Daten!E2,Daten!E$2:E$33,0) -> 31 | F2: =RANK(Daten!F2,Daten!F$2:F$33,0) -> 4 | G2: =RANK(Daten!G2,Daten!G$2:G$33,0) -> 2 | H2: =RANK(Daten!H2,Daten!H$2:H$33,0) -> 9 | I2: =RANK(Daten!I2,Daten!I$2:I$33,0) -> 2 | J2: =RANK(Daten!J2,Daten!J$2:J$33,0) -> 5 | K2: =RANK(Daten!K2,Daten!K$2:K$33,0) -> 3 | L2: =RANK(Daten!L2,Daten!L$2:L$33,1) -> 5 | M2: =RANK(Daten!M2,Daten!M$2:M$33,0) -> 3 | N2: =RANK(Daten!N2,Daten!N$2:N$33,0) -> 4 | O2: =RANK(Daten!O2,Daten!O$2:O$33,0) -> 1 | P2: =RANK(Daten!P2,Daten!P$2:P$33,0) -> 2 | Q2: =RANK(Daten!Q2,Daten!Q$2:Q$33,0) -> 2 | R2: =IF(Daten!R2="","",RANK(Daten!R2,Daten!R$2:R$33,0)) -> 1 | S2: =IF(Daten!S2="","",RANK(Daten!S2,Daten!S$2:S$33,0)) -> 1 | T2: =IF(Daten!T2="","",RANK(Daten!T2,Daten!T$2:T$33,0)) -> 2 | U2: =IF(Daten!U2="","",RANK(Daten!U2,Daten!U$2:U$33,0)) -> 11 | V2: =IF(Daten!V2="","",RANK(Daten!V2,Daten!V$2:V$33,0)) -> 1 | W2: =IF(Daten!W2="","",RANK(Daten!W2,Daten!W$2:W$33,1)) -> 5 | X2: =COUNTIF(B2:Q2,"<=3") -> 9 | Y2: =COUNTIF(B2:Q2,1) -> 2
A3: =Daten!A3 -> Alabama Crimson Tide | B3: =RANK(Daten!B3,Daten!B$2:B$33,1) -> 5 | C3: =RANK(Daten!C3,Daten!C$2:C$33,0) -> 3 | D3: =RANK(Daten!D3,Daten!D$2:D$33,0) -> 2 | E3: =RANK(Daten!E3,Daten!E$2:E$33,0) -> 28 | F3: =RANK(Daten!F3,Daten!F$2:F$33,0) -> 1 | G3: =RANK(Daten!G3,Daten!G$2:G$33,0) -> 5 | H3: =RANK(Daten!H3,Daten!H$2:H$33,0) -> 1 | I3: =RANK(Daten!I3,Daten!I$2:I$33,0) -> 1 | J3: =RANK(Daten!J3,Daten!J$2:J$33,0) -> 8 | K3: =RANK(Daten!K3,Daten!K$2:K$33,0) -> 8 | L3: =RANK(Daten!L3,Daten!L$2:L$33,1) -> 16 | M3: =RANK(Daten!M3,Daten!M$2:M$33,0) -> 16 | N3: =RANK(Daten!N3,Daten!N$2:N$33,0) -> 22 | O3: =RANK(Daten!O3,Daten!O$2:O$33,0) -> 3 | P3: =RANK(Daten!P3,Daten!P$2:P$33,0) -> 7 | Q3: =RANK(Daten!Q3,Daten!Q$2:Q$33,0) -> 1 | R3: =IF(Daten!R3="","",RANK(Daten!R3,Daten!R$2:R$33,0)) -> 3 | S3: =IF(Daten!S3="","",RANK(Daten!S3,Daten!S$2:S$33,0)) -> 2 | T3: =IF(Daten!T3="","",RANK(Daten!T3,Daten!T$2:T$33,0)) -> 4 | U3: =IF(Daten!U3="","",RANK(Daten!U3,Daten!U$2:U$33,0)) -> 7 | V3: =IF(Daten!V3="","",RANK(Daten!V3,Daten!V$2:V$33,0)) -> 2 | W3: =IF(Daten!W3="","",RANK(Daten!W3,Daten!W$2:W$33,1)) -> 5 | X3: =COUNTIF(B3:Q3,"<=3") -> 7 | Y3: =COUNTIF(B3:Q3,1) -> 4
A4: =Daten!A4 -> Notre Dame Fighting Irish | B4: =RANK(Daten!B4,Daten!B$2:B$33,1) -> 7 | C4: =RANK(Daten!C4,Daten!C$2:C$33,0) -> 4 | D4: =RANK(Daten!D4,Daten!D$2:D$33,0) -> 2 | E4: =RANK(Daten!E4,Daten!E$2:E$33,0) -> 15 | F4: =RANK(Daten!F4,Daten!F$2:F$33,0) -> 2 | G4: =RANK(Daten!G4,Daten!G$2:G$33,0) -> 2 | H4: =RANK(Daten!H4,Daten!H$2:H$33,0) -> 17 | I4: =RANK(Daten!I4,Daten!I$2:I$33,0) -> 6 | J4: =RANK(Daten!J4,Daten!J$2:J$33,0) -> 11 | K4: =RANK(Daten!K4,Daten!K$2:K$33,0) -> 16 | L4: =RANK(Daten!L4,Daten!L$2:L$33,1) -> 19 | M4: =RANK(Daten!M4,Daten!M$2:M$33,0) -> 31 | N4: =RANK(Daten!N4,Daten!N$2:N$33,0) -> 24 | O4: =RANK(Daten!O4,Daten!O$2:O$33,0) -> 17 | P4: =RANK(Daten!P4,Daten!P$2:P$33,0) -> 22 | Q4: =RANK(Daten!Q4,Daten!Q$2:Q$33,0) -> 6 | R4: =IF(Daten!R4="","",RANK(Daten!R4,Daten!R$2:R$33,0)) -> 9 | S4: =IF(Daten!S4="","",RANK(Daten!S4,Daten!S$2:S$33,0)) -> 14 | T4: =IF(Daten!T4="","",RANK(Daten!T4,Daten!T$2:T$33,0)) -> 8 | U4: =IF(Daten!U4="","",RANK(Daten!U4,Daten!U$2:U$33,0)) -> 4 | V4: =IF(Daten!V4="","",RANK(Daten!V4,Daten!V$2:V$33,0)) -> 9 | W4: =IF(Daten!W4="","",RANK(Daten!W4,Daten!W$2:W$33,1)) -> 19 | X4: =COUNTIF(B4:Q4,"<=3") -> 3 | Y4: =COUNTIF(B4:Q4,1) -> 0
A5: =Daten!A5 -> Michigan Wolverines | B5: =RANK(Daten!B5,Daten!B$2:B$33,1) -> 3 | C5: =RANK(Daten!C5,Daten!C$2:C$33,0) -> 1 | D5: =RANK(Daten!D5,Daten!D$2:D$33,0) -> 4 | E5: =RANK(Daten!E5,Daten!E$2:E$33,0) -> 30 | F5: =RANK(Daten!F5,Daten!F$2:F$33,0) -> 8 | G5: =RANK(Daten!G5,Daten!G$2:G$33,0) -> 6 | H5: =RANK(Daten!H5,Daten!H$2:H$33,0) -> 15 | I5: =RANK(Daten!I5,Daten!I$2:I$33,0) -> 6 | J5: =RANK(Daten!J5,Daten!J$2:J$33,0) -> 14 | K5: =RANK(Daten!K5,Daten!K$2:K$33,0) -> 1 | L5: =RANK(Daten!L5,Daten!L$2:L$33,1) -> 14 | M5: =RANK(Daten!M5,Daten!M$2:M$33,0) -> 6 | N5: =RANK(Daten!N5,Daten!N$2:N$33,0) -> 21 | O5: =RANK(Daten!O5,Daten!O$2:O$33,0) -> 17 | P5: =RANK(Daten!P5,Daten!P$2:P$33,0) -> 29 | Q5: =RANK(Daten!Q5,Daten!Q$2:Q$33,0) -> 7 | R5: =IF(Daten!R5="","",RANK(Daten!R5,Daten!R$2:R$33,0)) -> 10 | S5: =IF(Daten!S5="","",RANK(Daten!S5,Daten!S$2:S$33,0)) -> 10 | T5: =IF(Daten!T5="","",RANK(Daten!T5,Daten!T$2:T$33,0)) -> 11 | U5: =IF(Daten!U5="","",RANK(Daten!U5,Daten!U$2:U$33,0)) -> 4 | V5: =IF(Daten!V5="","",RANK(Daten!V5,Daten!V$2:V$33,0)) -> 10 | W5: =IF(Daten!W5="","",RANK(Daten!W5,Daten!W$2:W$33,1)) -> 4 | X5: =COUNTIF(B5:Q5,"<=3") -> 3 | Y5: =COUNTIF(B5:Q5,1) -> 2
A6: =Daten!A6 -> Boise State Broncos | B6: =RANK(Daten!B6,Daten!B$2:B$33,1) -> 32 | C6: =RANK(Daten!C6,Daten!C$2:C$33,0) -> 32 | D6: =RANK(Daten!D6,Daten!D$2:D$33,0) -> 5 | E6: =RANK(Daten!E6,Daten!E$2:E$33,0) -> 13 | F6: =RANK(Daten!F6,Daten!F$2:F$33,0) -> 23 | G6: =RANK(Daten!G6,Daten!G$2:G$33,0) -> 23 | H6: =RANK(Daten!H6,Daten!H$2:H$33,0) -> 30 | I6: =RANK(Daten!I6,Daten!I$2:I$33,0) -> 12 | J6: =RANK(Daten!J6,Daten!J$2:J$33,0) -> 14 | K6: =RANK(Daten!K6,Daten!K$2:K$33,0) -> 32 | L6: =RANK(Daten!L6,Daten!L$2:L$33,1) -> 30 | M6: =RANK(Daten!M6,Daten!M$2:M$33,0) -> 26 | N6: =RANK(Daten!N6,Daten!N$2:N$33,0) -> 9 | O6: =RANK(Daten!O6,Daten!O$2:O$33,0) -> 27 | P6: =RANK(Daten!P6,Daten!P$2:P$33,0) -> 32 | Q6: =RANK(Daten!Q6,Daten!Q$2:Q$33,0) -> 29 | R6: =IF(Daten!R6="","",RANK(Daten!R6,Daten!R$2:R$33,0)) -> 32 | S6: =IF(Daten!S6="","",RANK(Daten!S6,Daten!S$2:S$33,0)) -> 31 | T6: =IF(Daten!T6="","",RANK(Daten!T6,Daten!T$2:T$33,0)) -> 30 | U6: =IF(Daten!U6="","",RANK(Daten!U6,Daten!U$2:U$33,0)) -> 24 | V6: =IF(Daten!V6="","",RANK(Daten!V6,Daten!V$2:V$33,0)) -> 31 | W6: =IF(Daten!W6="","",RANK(Daten!W6,Daten!W$2:W$33,1)) -> 19 | X6: =COUNTIF(B6:Q6,"<=3") -> 0 | Y6: =COUNTIF(B6:Q6,1) -> 0
A7: =Daten!A7 -> Oklahoma Sooners | B7: =RANK(Daten!B7,Daten!B$2:B$33,1) -> 29 | C7: =RANK(Daten!C7,Daten!C$2:C$33,0) -> 6 | D7: =RANK(Daten!D7,Daten!D$2:D$33,0) -> 6 | E7: =RANK(Daten!E7,Daten!E$2:E$33,0) -> 19 | F7: =RANK(Daten!F7,Daten!F$2:F$33,0) -> 3 | G7: =RANK(Daten!G7,Daten!G$2:G$33,0) -> 2 | H7: =RANK(Daten!H7,Daten!H$2:H$33,0) -> 6 | I7: =RANK(Daten!I7,Daten!I$2:I$33,0) -> 4 | J7: =RANK(Daten!J7,Daten!J$2:J$33,0) -> 11 | K7: =RANK(Daten!K7,Daten!K$2:K$33,0) -> 14 | L7: =RANK(Daten!L7,Daten!L$2:L$33,1) -> 6 | M7: =RANK(Daten!M7,Daten!M$2:M$33,0) -> 22 | N7: =RANK(Daten!N7,Daten!N$2:N$33,0) -> 17 | O7: =RANK(Daten!O7,Daten!O$2:O$33,0) -> 17 | P7: =RANK(Daten!P7,Daten!P$2:P$33,0) -> 19 | Q7: =RANK(Daten!Q7,Daten!Q$2:Q$33,0) -> 11 | R7: =IF(Daten!R7="","",RANK(Daten!R7,Daten!R$2:R$33,0)) -> 12 | S7: =IF(Daten!S7="","",RANK(Daten!S7,Daten!S$2:S$33,0)) -> 15 | T7: =IF(Daten!T7="","",RANK(Daten!T7,Daten!T$2:T$33,0)) -> 13 | U7: =IF(Daten!U7="","",RANK(Daten!U7,Daten!U$2:U$33,0)) -> 24 | V7: =IF(Daten!V7="","",RANK(Daten!V7,Daten!V$2:V$33,0)) -> 8 | W7: =IF(Daten!W7="","",RANK(Daten!W7,Daten!W$2:W$33,1)) -> 14 | X7: =COUNTIF(B7:Q7,"<=3") -> 2 | Y7: =COUNTIF(B7:Q7,1) -> 0
A8: =Daten!A8 -> Texas Longhorns | B8: =RANK(Daten!B8,Daten!B$2:B$33,1) -> 26 | C8: =RANK(Daten!C8,Daten!C$2:C$33,0) -> 4 | D8: =RANK(Daten!D8,Daten!D$2:D$33,0) -> 7 | E8: =RANK(Daten!E8,Daten!E$2:E$33,0) -> 22 | F8: =RANK(Daten!F8,Daten!F$2:F$33,0) -> 8 | G8: =RANK(Daten!G8,Daten!G$2:G$33,0) -> 11 | H8: =RANK(Daten!H8,Daten!H$2:H$33,0) -> 4 | I8: =RANK(Daten!I8,Daten!I$2:I$33,0) -> 9 | J8: =RANK(Daten!J8,Daten!J$2:J$33,0) -> 11 | K8: =RANK(Daten!K8,Daten!K$2:K$33,0) -> 7 | L8: =RANK(Daten!L8,Daten!L$2:L$33,1) -> 10 | M8: =RANK(Daten!M8,Daten!M$2:M$33,0) -> 5 | N8: =RANK(Daten!N8,Daten!N$2:N$33,0) -> 2 | O8: =RANK(Daten!O8,Daten!O$2:O$33,0) -> 13 | P8: =RANK(Daten!P8,Daten!P$2:P$33,0) -> 5 | Q8: =RANK(Daten!Q8,Daten!Q$2:Q$33,0) -> 5 | R8: =IF(Daten!R8="","",RANK(Daten!R8,Daten!R$2:R$33,0)) -> 14 | S8: =IF(Daten!S8="","",RANK(Daten!S8,Daten!S$2:S$33,0)) -> 13 | T8: =IF(Daten!T8="","",RANK(Daten!T8,Daten!T$2:T$33,0)) -> 15 | U8: =IF(Daten!U8="","",RANK(Daten!U8,Daten!U$2:U$33,0)) -> 11 | V8: =IF(Daten!V8="","",RANK(Daten!V8,Daten!V$2:V$33,0)) -> 12 | W8: =IF(Daten!W8="","",RANK(Daten!W8,Daten!W$2:W$33,1)) -> 1 | X8: =COUNTIF(B8:Q8,"<=3") -> 1 | Y8: =COUNTIF(B8:Q8,1) -> 0
A9: =Daten!A9 -> USC Trojans | B9: =RANK(Daten!B9,Daten!B$2:B$33,1) -> 25 | C9: =RANK(Daten!C9,Daten!C$2:C$33,0) -> 10 | D9: =RANK(Daten!D9,Daten!D$2:D$33,0) -> 8 | E9: =RANK(Daten!E9,Daten!E$2:E$33,0) -> 21 | F9: =RANK(Daten!F9,Daten!F$2:F$33,0) -> 5 | G9: =RANK(Daten!G9,Daten!G$2:G$33,0) -> 1 | H9: =RANK(Daten!H9,Daten!H$2:H$33,0) -> 3 | I9: =RANK(Daten!I9,Daten!I$2:I$33,0) -> 24 | J9: =RANK(Daten!J9,Daten!J$2:J$33,0) -> 14 | K9: =RANK(Daten!K9,Daten!K$2:K$33,0) -> 17 | L9: =RANK(Daten!L9,Daten!L$2:L$33,1) -> 6 | M9: =RANK(Daten!M9,Daten!M$2:M$33,0) -> 10 | N9: =RANK(Daten!N9,Daten!N$2:N$33,0) -> 1 | O9: =RANK(Daten!O9,Daten!O$2:O$33,0) -> 23 | P9: =RANK(Daten!P9,Daten!P$2:P$33,0) -> 3 | Q9: =RANK(Daten!Q9,Daten!Q$2:Q$33,0) -> 15 | R9: =IF(Daten!R9="","",RANK(Daten!R9,Daten!R$2:R$33,0)) -> 4 | S9: =IF(Daten!S9="","",RANK(Daten!S9,Daten!S$2:S$33,0)) -> 4 | T9: =IF(Daten!T9="","",RANK(Daten!T9,Daten!T$2:T$33,0)) -> 2 | U9: =IF(Daten!U9="","",RANK(Daten!U9,Daten!U$2:U$33,0)) -> 2 | V9: =IF(Daten!V9="","",RANK(Daten!V9,Daten!V$2:V$33,0)) -> 6 | W9: =IF(Daten!W9="","",RANK(Daten!W9,Daten!W$2:W$33,1)) -> 15 | X9: =COUNTIF(B9:Q9,"<=3") -> 4 | Y9: =COUNTIF(B9:Q9,1) -> 2
A10: =Daten!A10 -> Penn State Nittany Lions | B10: =RANK(Daten!B10,Daten!B$2:B$33,1) -> 14 | C10: =RANK(Daten!C10,Daten!C$2:C$33,0) -> 7 | D10: =RANK(Daten!D10,Daten!D$2:D$33,0) -> 9 | E10: =RANK(Daten!E10,Daten!E$2:E$33,0) -> 14 | F10: =RANK(Daten!F10,Daten!F$2:F$33,0) -> 15 | G10: =RANK(Daten!G10,Daten!G$2:G$33,0) -> 18 | H10: =RANK(Daten!H10,Daten!H$2:H$33,0) -> 4 | I10: =RANK(Daten!I10,Daten!I$2:I$33,0) -> 12 | J10: =RANK(Daten!J10,Daten!J$2:J$33,0) -> 23 | K10: =RANK(Daten!K10,Daten!K$2:K$33,0) -> 2 | L10: =RANK(Daten!L10,Daten!L$2:L$33,1) -> 27 | M10: =RANK(Daten!M10,Daten!M$2:M$33,0) -> 11 | N10: =RANK(Daten!N10,Daten!N$2:N$33,0) -> 30 | O10: =RANK(Daten!O10,Daten!O$2:O$33,0) -> 5 | P10: =RANK(Daten!P10,Daten!P$2:P$33,0) -> 13 | Q10: =RANK(Daten!Q10,Daten!Q$2:Q$33,0) -> 9 | R10: =IF(Daten!R10="","",RANK(Daten!R10,Daten!R$2:R$33,0)) -> 5 | S10: =IF(Daten!S10="","",RANK(Daten!S10,Daten!S$2:S$33,0)) -> 11 | T10: =IF(Daten!T10="","",RANK(Daten!T10,Daten!T$2:T$33,0)) -> 9 | U10: =IF(Daten!U10="","",RANK(Daten!U10,Daten!U$2:U$33,0)) -> 11 | V10: =IF(Daten!V10="","",RANK(Daten!V10,Daten!V$2:V$33,0)) -> 11 | W10: =IF(Daten!W10="","",RANK(Daten!W10,Daten!W$2:W$33,1)) -> 15 | X10: =COUNTIF(B10:Q10,"<=3") -> 1 | Y10: =COUNTIF(B10:Q10,1) -> 0
A11: =Daten!A11 -> Nebraska Cornhuskers | B11: =RANK(Daten!B11,Daten!B$2:B$33,1) -> 19 | C11: =RANK(Daten!C11,Daten!C$2:C$33,0) -> 8 | D11: =RANK(Daten!D11,Daten!D$2:D$33,0) -> 10 | E11: =RANK(Daten!E11,Daten!E$2:E$33,0) -> 17 | F11: =RANK(Daten!F11,Daten!F$2:F$33,0) -> 7 | G11: =RANK(Daten!G11,Daten!G$2:G$33,0) -> 6 | H11: =RANK(Daten!H11,Daten!H$2:H$33,0) -> 12 | I11: =RANK(Daten!I11,Daten!I$2:I$33,0) -> 24 | J11: =RANK(Daten!J11,Daten!J$2:J$33,0) -> 23 | K11: =RANK(Daten!K11,Daten!K$2:K$33,0) -> 12 | L11: =RANK(Daten!L11,Daten!L$2:L$33,1) -> 6 | M11: =RANK(Daten!M11,Daten!M$2:M$33,0) -> 28 | N11: =RANK(Daten!N11,Daten!N$2:N$33,0) -> 6 | O11: =RANK(Daten!O11,Daten!O$2:O$33,0) -> 27 | P11: =RANK(Daten!P11,Daten!P$2:P$33,0) -> 13 | Q11: =RANK(Daten!Q11,Daten!Q$2:Q$33,0) -> 31 | R11: =IF(Daten!R11="","",RANK(Daten!R11,Daten!R$2:R$33,0)) -> 15 | S11: =IF(Daten!S11="","",RANK(Daten!S11,Daten!S$2:S$33,0)) -> 20 | T11: =IF(Daten!T11="","",RANK(Daten!T11,Daten!T$2:T$33,0)) -> 20 | U11: =IF(Daten!U11="","",RANK(Daten!U11,Daten!U$2:U$33,0)) -> 7 | V11: =IF(Daten!V11="","",RANK(Daten!V11,Daten!V$2:V$33,0)) -> 22 | W11: =IF(Daten!W11="","",RANK(Daten!W11,Daten!W$2:W$33,1)) -> 11 | X11: =COUNTIF(B11:Q11,"<=3") -> 0 | Y11: =COUNTIF(B11:Q11,1) -> 0
A12: =Daten!A12 -> Tennessee Volunteers | B12: =RANK(Daten!B12,Daten!B$2:B$33,1) -> 2 | C12: =RANK(Daten!C12,Daten!C$2:C$33,0) -> 11 | D12: =RANK(Daten!D12,Daten!D$2:D$33,0) -> 11 | E12: =RANK(Daten!E12,Daten!E$2:E$33,0) -> 18 | F12: =RANK(Daten!F12,Daten!F$2:F$33,0) -> 15 | G12: =RANK(Daten!G12,Daten!G$2:G$33,0) -> 23 | H12: =RANK(Daten!H12,Daten!H$2:H$33,0) -> 6 | I12: =RANK(Daten!I12,Daten!I$2:I$33,0) -> 12 | J12: =RANK(Daten!J12,Daten!J$2:J$33,0) -> 20 | K12: =RANK(Daten!K12,Daten!K$2:K$33,0) -> 6 | L12: =RANK(Daten!L12,Daten!L$2:L$33,1) -> 4 | M12: =RANK(Daten!M12,Daten!M$2:M$33,0) -> 18 | N12: =RANK(Daten!N12,Daten!N$2:N$33,0) -> 13 | O12: =RANK(Daten!O12,Daten!O$2:O$33,0) -> 17 | P12: =RANK(Daten!P12,Daten!P$2:P$33,0) -> 9 | Q12: =RANK(Daten!Q12,Daten!Q$2:Q$33,0) -> 22 | R12: =IF(Daten!R12="","",RANK(Daten!R12,Daten!R$2:R$33,0)) -> 13 | S12: =IF(Daten!S12="","",RANK(Daten!S12,Daten!S$2:S$33,0)) -> 8 | T12: =IF(Daten!T12="","",RANK(Daten!T12,Daten!T$2:T$33,0)) -> 9 | U12: =IF(Daten!U12="","",RANK(Daten!U12,Daten!U$2:U$33,0)) -> 11 | V12: =IF(Daten!V12="","",RANK(Daten!V12,Daten!V$2:V$33,0)) -> 17 | W12: =IF(Daten!W12="","",RANK(Daten!W12,Daten!W$2:W$33,1)) -> 2 | X12: =COUNTIF(B12:Q12,"<=3") -> 1 | Y12: =COUNTIF(B12:Q12,1) -> 0
A13: =Daten!A13 -> Georgia Bulldogs | B13: =RANK(Daten!B13,Daten!B$2:B$33,1) -> 1 | C13: =RANK(Daten!C13,Daten!C$2:C$33,0) -> 9 | D13: =RANK(Daten!D13,Daten!D$2:D$33,0) -> 12 | E13: =RANK(Daten!E13,Daten!E$2:E$33,0) -> 29 | F13: =RANK(Daten!F13,Daten!F$2:F$33,0) -> 8 | G13: =RANK(Daten!G13,Daten!G$2:G$33,0) -> 11 | H13: =RANK(Daten!H13,Daten!H$2:H$33,0) -> 2 | I13: =RANK(Daten!I13,Daten!I$2:I$33,0) -> 4 | J13: =RANK(Daten!J13,Daten!J$2:J$33,0) -> 5 | K13: =RANK(Daten!K13,Daten!K$2:K$33,0) -> 9 | L13: =RANK(Daten!L13,Daten!L$2:L$33,1) -> 16 | M13: =RANK(Daten!M13,Daten!M$2:M$33,0) -> 14 | N13: =RANK(Daten!N13,Daten!N$2:N$33,0) -> 18 | O13: =RANK(Daten!O13,Daten!O$2:O$33,0) -> 5 | P13: =RANK(Daten!P13,Daten!P$2:P$33,0) -> 1 | Q13: =RANK(Daten!Q13,Daten!Q$2:Q$33,0) -> 3 | R13: =IF(Daten!R13="","",RANK(Daten!R13,Daten!R$2:R$33,0)) -> 8 | S13: =IF(Daten!S13="","",RANK(Daten!S13,Daten!S$2:S$33,0)) -> 6 | T13: =IF(Daten!T13="","",RANK(Daten!T13,Daten!T$2:T$33,0)) -> 7 | U13: =IF(Daten!U13="","",RANK(Daten!U13,Daten!U$2:U$33,0)) -> 4 | V13: =IF(Daten!V13="","",RANK(Daten!V13,Daten!V$2:V$33,0)) -> 4 | W13: =IF(Daten!W13="","",RANK(Daten!W13,Daten!W$2:W$33,1)) -> 15 | X13: =COUNTIF(B13:Q13,"<=3") -> 4 | Y13: =COUNTIF(B13:Q13,1) -> 2
... A33: =Daten!A33 -> Indiana Hoosiers | B33: =RANK(Daten!B33,Daten!B$2:B$33,1) -> 4 | C33: =RANK(Daten!C33,Daten!C$2:C$33,0) -> 31 | D33: =RANK(Daten!D33,Daten!D$2:D$33,0) -> 32 | E33: =RANK(Daten!E33,Daten!E$2:E$33,0) -> 32 | F33: =RANK(Daten!F33,Daten!F$2:F$33,0) -> 19 | G33: =RANK(Daten!G33,Daten!G$2:G$33,0) -> 18 | H33: =RANK(Daten!H33,Daten!H$2:H$33,0) -> 32 | I33: =RANK(Daten!I33,Daten!I$2:I$33,0) -> 9 | J33: =RANK(Daten!J33,Daten!J$2:J$33,0) -> 1 | K33: =RANK(Daten!K33,Daten!K$2:K$33,0) -> 28 | L33: =RANK(Daten!L33,Daten!L$2:L$33,1) -> 27 | M33: =RANK(Daten!M33,Daten!M$2:M$33,0) -> 12 | N33: =RANK(Daten!N33,Daten!N$2:N$33,0) -> 26 | O33: =RANK(Daten!O33,Daten!O$2:O$33,0) -> 5 | P33: =RANK(Daten!P33,Daten!P$2:P$33,0) -> 16 | Q33: =RANK(Daten!Q33,Daten!Q$2:Q$33,0) -> 25 | R33: =IF(Daten!R33="","",RANK(Daten!R33,Daten!R$2:R$33,0)) -> 31 | S33: =IF(Daten!S33="","",RANK(Daten!S33,Daten!S$2:S$33,0)) -> 31 | T33: =IF(Daten!T33="","",RANK(Daten!T33,Daten!T$2:T$33,0)) -> 32 | U33: =IF(Daten!U33="","",RANK(Daten!U33,Daten!U$2:U$33,0)) -> 24 | V33: =IF(Daten!V33="","",RANK(Daten!V33,Daten!V$2:V$33,0)) -> 32 | W33: =IF(Daten!W33="","",RANK(Daten!W33,Daten!W$2:W$33,1)) -> 30 | X33: =COUNTIF(B33:Q33,"<=3") -> 1 | Y33: =COUNTIF(B33:Q33,1) -> 1
A35: Einträge mit mind. 1 Top-3-Rang | B35: =COUNTIF(X2:X33,">0") -> 21
A36: Einträge ohne Top-3-Rang | B36: =COUNTIF(X2:X33,0) -> 11
A37: Verschiedene Nr. 1 (Einträge mit mind. 1 Rang 1) | B37: =COUNTIF(Y2:Y33,">0") -> 12

Sheet Kategorien
A1: # | B1: Kategorie | C1: Einheit | D1: Rang 1 = | E1: Wer gewinnt (Nr. 1) | F1: Datenqualität | G1: Mindestabstand im Spiel | H1: Zu nahe Paare | I1: Definition | J1: Quelle | K1: Hinweise | L1: Update-Plan
A2: 1 | B2: Universität gegründet | C2: Jahr | D2: älteste Uni | E2: Georgia Bulldogs | F2: hart | G2: ≥ 3.0 Jahre | H2: 20 | I2: Gründungsjahr der Universität. | J2: Wikipedia (Universitätsartikel) | K2: Georgia 1785 (älteste staatliche Uni der USA), Tennessee 1794, Michigan 1817. Drei Unis 1876 (Texas A&M, Oregon, Colorado). | L2: Nie.
A3: 2 | B3: Siege all-time | C3: Siege | D3: meiste | E3: Michigan Wolverines | F3: hart | G3: ≥ 20.0 Siege | H3: 38 | I3: Alle offiziell anerkannten Siege (nach NCAA-Aberkennungen), Stand Ende Saison 2025 inkl. Bowls/CFP. | J3: Wikipedia 'NCAA Division I FBS football win–loss records' (Haupttabelle, Stand nach Saison 2025) | K3: Michigan 1'021 vor Ohio State 990. Achtung: Die Conference-Untertabellen derselben Wikipedia-Seite sind noch Stand 2024 – nur Haupttabelle verwenden. | L3: Jährlich im Januar.
A4: 3 | B4: Siegquote all-time | C4: % | D4: höchste | E4: Ohio State Buckeyes | F4: hart | G4: ≥ 1 Prozentpunkt | H4: 40 | I4: (Siege + ½ Unentschieden) / Spiele, NCAA-Zählweise, Stand Ende 2025. | J4: Formel aus Siege + Hilfsspalten Niederlagen/Unentschieden | K4: Ohio State .737, Alabama/Notre Dame .733, Michigan .732 – sehr eng an der Spitze (Paar-Check). | L4: Jährlich.
A5: 4 | B5: Jahre seit letztem AP-Nationaltitel | C5: Jahre | D5: längste Durststrecke | E5: Iowa Hawkeyes, Washington Huskies, Wisconsin Badgers | F5: hart | G5: ≥ 3.0 Jahre | H5: 26 | I5: Referenzjahr minus Saison des letzten AP-Poll-Nationaltitels (seit 1936); ohne AP-Titel: Jahre seit erster Football-Saison des Programms. | J5: Wikipedia 'List of NCAA Division I FBS football bowl records' (Spalte 'Last AP Championship') + Programmstart | K5: Formel aus Hilfsspalten. Coaches-Poll-Titel (Washington 1991, Iowa 1958) zählen nicht – AP als einheitliche Quelle (Regel 8). | L5: Jährlich im Januar (Referenzjahr + Titelsaison).
A6: 5 | B6: AP-Nationaltitel | C6: Titel | D6: meiste | E6: Alabama Crimson Tide | F6: hart | G6: ≥ 1.0 Titel | H6: 79 | I6: Anzahl Nationaltitel im AP-Poll (seit 1936), inkl. Saison 2025. | J6: Wikipedia 'List of NCAA Division I FBS football bowl records' (Klammerwert bei 'Last AP Championship') | K6: Alabama 12, Notre Dame 8, Oklahoma 7. 10 Programme ohne AP-Titel – sparsam als Runde einsetzen. 'Claimed titles' bewusst nicht verwendet (widersprüchlich). | L6: Jährlich im Januar.
A7: 6 | B7: Heisman-Sieger | C7: Anzahl | D7: meiste | E7: USC Trojans | F7: hart | G7: ≥ 1.0 Sieger | H7: 89 | I7: Anzahl Heisman-Trophy-Gewinner des Programms, inkl. 2025 (Fernando Mendoza, Indiana). USC 8 inkl. Reggie Bush (2005, 2024 wiedereingesetzt). | J7: Wikipedia 'Heisman Trophy' (Sieger nach Schule); NFL.com 13.12.2025 (Mendoza) | K7: 12 Programme mit 0 – nur sparsam als Runde. Archie Griffin (Ohio State) zählt 2x. | L7: Jährlich im Dezember.
A8: 7 | B8: Bowl-Siege all-time | C8: Siege | D8: meiste | E8: Alabama Crimson Tide | F8: hart | G8: ≥ 2.0 Siege | H8: 40 | I8: Siege in NCAA-sanktionierten Bowl-Spielen inkl. CFP-Spiele in Bowls, Stand nach Bowl-Saison 2025/26 (19.01.2026). | J8: Wikipedia 'List of NCAA Division I FBS football bowl records' | K8: Alabama 46. Bowl-Teilnahmen bewusst nicht als Attribut (stark korreliert, Regel 8). | L8: Jährlich im Januar.
A9: 8 | B9: CFP-Teilnahmen | C9: Anzahl | D9: meiste | E9: Alabama Crimson Tide | F9: hart | G9: ≥ 1.0 Teilnahmen | H9: 110 | I9: Teilnahmen am College Football Playoff (2014–2025, 4er- und 12er-Format). | J9: Wikipedia 'List of NCAA Division I FBS football bowl records' (Spalte 'CFP Playoff Appearances') | K9: Alabama 8, Ohio State/Clemson 7. 9 Programme mit 0 – sparsam einsetzen. | L9: Jährlich im Dezember.
A10: 9 | B10: Siege Saison 2025 | C10: Siege | D10: meiste | E10: Indiana Hoosiers | F10: hart | G10: ≥ 1.0 Siege | H10: 40 | I10: Siege in der Saison 2025 inkl. Conference Championship, Bowl und CFP (Stand 19.01.2026). | J10: ESPN/ACC/Sports-Reference Conference-Standings 2025 (SEC, Big Ten, ACC, Big 12, MWC, Independent) | K10: Indiana 16-0 (Nationalmeister), Miami 13-3, Oregon 13-2, Ole Miss 13-2. Viele Gleichstände (9 Siege: 6 Teams). | L10: Jährlich im Januar.
A11: 10 | B11: Stadionkapazität | C11: Plätze | D11: grösstes | E11: Michigan Wolverines | F11: mittel | G11: ≥ 1500.0 Plätze | H11: 22 | I11: Offizielle Kapazität des Heimstadions Saison 2025/26. | J11: Wikipedia 'List of American football stadiums by capacity' / Stadionartikel | K11: Michigan 107'601, Penn State 106'304 (Umbau), Ohio State 102'780. Miami spielt im NFL-Stadion (65'326). Kapazitäten vor Livegang mit Stand 2026 prüfen. | L11: Jährlich vor Saisonstart.
A12: 11 | B12: Stadion eröffnet | C12: Jahr | D12: ältestes Stadion | E12: Ole Miss Rebels | F12: hart | G12: ≥ 2.0 Jahre | H12: 46 | I12: Eröffnungsjahr des Heimstadions (Erstnutzung). | J12: Wikipedia Stadionartikel | K12: Vaught-Hemingway (Ole Miss) 1915, Camp Randall 1917, Husky Stadium 1920. Jüngstes: Rice-Eccles 1998. | L12: Bei Stadionwechsel.
A13: 12 | B13: Studierende | C13: Tsd. | D13: grösste Uni | E13: Arizona State Sun Devils | F13: mittel | G13: ≥ 10 % Unterschied | H13: 77 | I13: Gesamtzahl Studierende am Hauptcampus (Herbst 2024, auf Hundert gerundet). | J13: Wikipedia Universitätsartikel (Infobox 'Students') | K13: Arizona State (Tempe) und Texas A&M ca. 80'000; Notre Dame und TCU ca. 13'000. Zählweise (Campus vs. Gesamtsystem) vor Livegang vereinheitlichen. | L13: Alle 2 Jahre.
... A23: 22 | B23: Schnellster 40-Yard eines Alumni | C23: s | D23: schnellster | E23: Texas Longhorns | F23: mittel | G23: ≥ 0.02 s | H23: 135 | I23: Beste offizielle 40-Yard-Zeit eines Programm-Alumni beim Combine seit 2000. | J23: nflverse draft_picks / combine / rosters, Stand 25.09.2026 | K23: 32/32 mit Wert. Hundertstel-Raster → Gleichstände. | L23: Jährlich im März.
A26: Hinweise
A27: Auswahl: 32 bekannteste FBS-Programme (Blue Bloods + aktuelle CFP-Teams 2025: Indiana, Miami, Ole Miss, Texas Tech, Oregon, Utah, Boise State). Stand 23.09.2026, Daten Ende Saison 2025 (CFP-Finale 19.01.2026: Indiana – Miami).
A28: Änderungen v2 → v3 (25.09.2026): 6 neue Kategorien aus nflverse (Draft-Picks und Erstrunden-Picks seit 1980, Pro-Bowler und Hall-of-Famer gedraftet seit 1980, Combine-Teilnehmer seit 2000, schnellster 40-Yard). Neue Hilfsspalte: Schulname in nflverse (für Script-Updates).
A29: Änderungen v1 → v2 (25.09.2026): 'Unentschieden all-time' gestrichen (zu viele Kleinstwerte, historisch bedeutungslos für die Zielgruppe). Neu: Cheftrainer-Gehalt 2025 und Alumni auf NFL-Kadern Woche 1 2026; Hilfsspalte Head Coach 2025.
A30: Erfolgsdaten (Siege, Siegquote, Bowl-Siege, CFP, AP-Titel, Heisman, Siege 2025, Draft 2026) sind quellenbelegt (Wikipedia-Listen, ESPN/Sports-Reference-Standings, AP-Draftliste). Stadion-, Studierenden- und Einwohnerzahlen aus Wikipedia-Artikeln – vor Livegang stichprobenartig prüfen (Qualität 'mittel').
A31: Bewusst weggelassen: Bowl-Teilnahmen (korreliert mit Bowl-Siegen), 'claimed' Nationaltitel (widersprüchliche Zählweisen), Conference-Titel (Conference-Wechsel machen Vergleich schief), Consensus All-Americans (korreliert mit Titeln), Höhe ü. M. (zu viele Gleichstände).
A32: Drei Attribute mit vielen Nullen (AP-Titel, Heisman, CFP-Teilnahmen) – höchstens eines davon pro Spielrunde.
A33: Mindestabstand: siehe Blatt 'Paar-Check'.
A34: Vor Livegang prüfen (v2): Trainergehälter privater Unis (Schätzwerte), Texas Tech (Sekundärquelle), Alumni-Zählung (Kickoff-Stand, ohne Practice Squad), sowie weiterhin Stadion-/Studierenden-/Einwohnerzahlen.

Sheet Paar-Check
A1: Kategorie | B1: Programm A | C1: Wert A | D1: Programm B | E1: Wert B | F1: Differenz | G1: Gleichstand?
A2: Universität gegründet | B2: Ohio State Buckeyes | C2: 1870 | D2: Nebraska Cornhuskers | E2: 1869 | F2: 1
A3: Universität gegründet | B3: Oklahoma Sooners | C3: 1890 | D3: Clemson Tigers | E3: 1889 | F3: 1
A4: Universität gegründet | B4: Texas Longhorns | C4: 1883 | D4: Arizona State Sun Devils | E4: 1885 | F4: 2
A5: Universität gegründet | B5: Penn State Nittany Lions | C5: 1855 | D5: Florida Gators | E5: 1853 | F5: 2
A6: Universität gegründet | B6: Penn State Nittany Lions | C6: 1855 | D6: Auburn Tigers | E6: 1856 | F6: 1
A7: Universität gegründet | B7: Penn State Nittany Lions | C7: 1855 | D7: Michigan State Spartans | E7: 1855 | F7: 0 | G7: ja
A8: Universität gegründet | B8: Florida State Seminoles | C8: 1851 | D8: Florida Gators | E8: 1853 | F8: 2
A9: Universität gegründet | B9: Florida State Seminoles | C9: 1851 | D9: Utah Utes | E9: 1850 | F9: 1
A10: Universität gegründet | B10: LSU Tigers | C10: 1860 | D10: Washington Huskies | E10: 1861 | F10: 1
A11: Universität gegründet | B11: Miami Hurricanes | C11: 1925 | D11: Texas Tech Red Raiders | E11: 1923 | F11: 2
A12: Universität gegründet | B12: Florida Gators | C12: 1853 | D12: Michigan State Spartans | E12: 1855 | F12: 2
A13: Universität gegründet | B13: Auburn Tigers | C13: 1856 | D13: Michigan State Spartans | E13: 1855 | F13: 1
A14: Universität gegründet | B14: Texas A&M Aggies | C14: 1876 | D14: Oregon Ducks | E14: 1876 | F14: 0 | G14: ja
A15: Universität gegründet | B15: Texas A&M Aggies | C15: 1876 | D15: Colorado Buffaloes | E15: 1876 | F15: 0 | G15: ja
A16: Universität gegründet | B16: Utah Utes | C16: 1850 | D16: Wisconsin Badgers | E16: 1848 | F16: 2
A17: Universität gegründet | B17: Utah Utes | C17: 1850 | D17: Ole Miss Rebels | E17: 1848 | F17: 2
A18: Universität gegründet | B18: Wisconsin Badgers | C18: 1848 | D18: Ole Miss Rebels | E18: 1848 | F18: 0 | G18: ja
A19: Universität gegründet | B19: Wisconsin Badgers | C19: 1848 | D19: Iowa Hawkeyes | E19: 1847 | F19: 1
A20: Universität gegründet | B20: Oregon Ducks | C20: 1876 | D20: Colorado Buffaloes | E20: 1876 | F20: 0 | G20: ja
A21: Universität gegründet | B21: Ole Miss Rebels | C21: 1848 | D21: Iowa Hawkeyes | E21: 1847 | F21: 1
A22: Siege all-time | B22: Ohio State Buckeyes | C22: 990 | D22: Alabama Crimson Tide | E22: 985 | F22: 5
A23: Siege all-time | B23: Ohio State Buckeyes | C23: 990 | D23: Notre Dame Fighting Irish | E23: 972 | F23: 18
A24: Siege all-time | B24: Ohio State Buckeyes | C24: 990 | D24: Texas Longhorns | E24: 972 | F24: 18
A25: Siege all-time | B25: Alabama Crimson Tide | C25: 985 | D25: Notre Dame Fighting Irish | E25: 972 | F25: 13
A26: Siege all-time | B26: Alabama Crimson Tide | C26: 985 | D26: Texas Longhorns | E26: 972 | F26: 13
A27: Siege all-time | B27: Notre Dame Fighting Irish | C27: 972 | D27: Oklahoma Sooners | E27: 960 | F27: 12
A28: Siege all-time | B28: Notre Dame Fighting Irish | C28: 972 | D28: Texas Longhorns | E28: 972 | F28: 0 | G28: ja
A29: Siege all-time | B29: Boise State Broncos | C29: 511 | D29: Indiana Hoosiers | E29: 521 | F29: 10
A30: Siege all-time | B30: Oklahoma Sooners | C30: 960 | D30: Texas Longhorns | E30: 972 | F30: 12
A31: Siege all-time | B31: Oklahoma Sooners | C31: 960 | D31: Penn State Nittany Lions | E31: 946 | F31: 14
A32: Siege all-time | B32: USC Trojans | C32: 886 | D32: Tennessee Volunteers | E32: 877 | F32: 9
A33: Siege all-time | B33: USC Trojans | C33: 886 | D33: Georgia Bulldogs | E33: 895 | F33: 9
A34: Siege all-time | B34: Penn State Nittany Lions | C34: 946 | D34: Nebraska Cornhuskers | E34: 927 | F34: 19
A35: Siege all-time | B35: Tennessee Volunteers | C35: 877 | D35: Georgia Bulldogs | E35: 895 | F35: 18
A36: Siege all-time | B36: LSU Tigers | C36: 818 | D36: Clemson Tigers | E36: 809 | F36: 9
A37: Siege all-time | B37: LSU Tigers | C37: 818 | D37: Auburn Tigers | E37: 807 | F37: 11
A38: Siege all-time | B38: Miami Hurricanes | C38: 676 | D38: Ole Miss Rebels | E38: 688 | F38: 12
A39: Siege all-time | B39: Florida Gators | C39: 767 | D39: Washington Huskies | E39: 783 | F39: 16
A40: Siege all-time | B40: Florida Gators | C40: 767 | D40: Wisconsin Badgers | E40: 749 | F40: 18
...
