Workbook

Sheet Football Records
A1: ID | B1: Category | C1: Record | D1: Holder | E1: Nation / Club | F1: Gender | G1: Value | H1: Unit | I1: Display | J1: Year set | K1: Years standing | L1: Competition | M1: Check | N1: Note
A2: 1 | B2: World Cup | C2: Most World Cup goals (career) | D2: Kylian Mbappé | E2: France | F2: M | G2: 22 | H2: goals | I2: 22 | J2: 2026 | K2: ='Notes & Sources'!$B$3-J2 -> 0 | L2: FIFA World Cup | M2: Checked online Sept 2026 | N2: Passed Messi (21) and Klose (16) in 2026
A3: 2 | B3: World Cup | C3: Most World Cup matches played | D3: Lionel Messi | E3: Argentina | F3: M | G3: 34 | H3: matches | I3: 34 | J3: 2026 | K3: ='Notes & Sources'!$B$3-J3 -> 0 | L3: FIFA World Cup | M3: Checked online Sept 2026
A4: 3 | B4: World Cup | C4: Most goals at a single World Cup | D4: Just Fontaine | E4: France | F4: M | G4: 13 | H4: goals | I4: 13 | J4: 1958 | K4: ='Notes & Sources'!$B$3-J4 -> 68 | L4: FIFA World Cup | M4: Checked online Sept 2026 | N4: Mbappé scored 10 in 2026
A5: 4 | B5: World Cup | C5: Most World Cup titles | D5: Brazil | E5: Brazil | F5: Team | G5: 5 | H5: titles | I5: 5 | J5: 2002 | K5: ='Notes & Sources'!$B$3-J5 -> 24 | L5: FIFA World Cup | M5: Checked online Sept 2026 | N5: Spain won 2026 (2nd title)
A6: 5 | B6: World Cup | C6: Most World Cup finals played | D6: Germany | E6: Germany | F6: Team | G6: 8 | H6: finals | I6: 8 | J6: 2014 | K6: ='Notes & Sources'!$B$3-J6 -> 12 | L6: FIFA World Cup | M6: Stable – unchanged since set
A7: 6 | B7: World Cup | C7: Most World Cup titles as a player | D7: Pelé | E7: Brazil | F7: M | G7: 3 | H7: titles | I7: 3 | J7: 1970 | K7: ='Notes & Sources'!$B$3-J7 -> 56 | L7: FIFA World Cup | M7: Stable – unchanged since set
A8: 7 | B8: World Cup | C8: Most World Cup titles as a coach | D8: Vittorio Pozzo | E8: Italy | F8: M | G8: 2 | H8: titles | I8: 2 | J8: 1938 | K8: ='Notes & Sources'!$B$3-J8 -> 88 | L8: FIFA World Cup | M8: Stable – unchanged since set
A9: 8 | B9: World Cup | C9: Most World Cup Golden Boots | D9: Kylian Mbappé | E9: France | F9: M | G9: 2 | H9: awards | I9: 2 | J9: 2026 | K9: ='Notes & Sources'!$B$3-J9 -> 0 | L9: FIFA World Cup | M9: Checked online Sept 2026 | N9: 2022 and 2026
A10: 9 | B10: World Cup | C10: Scored at the most World Cups | D10: Cristiano Ronaldo | E10: Portugal | F10: M | G10: 6 | H10: tournaments | I10: 6 | J10: 2026 | K10: ='Notes & Sources'!$B$3-J10 -> 0 | L10: FIFA World Cup | M10: Checked online Sept 2026 | N10: 2006–2026
A11: 10 | B11: World Cup | C11: Oldest World Cup goalscorer | D11: Roger Milla | E11: Cameroon | F11: M | G11: 42.11 | H11: years | I11: 42 y 39 d | J11: 1994 | K11: ='Notes & Sources'!$B$3-J11 -> 32 | L11: FIFA World Cup | M11: Stable – unchanged since set
A12: 11 | B12: World Cup | C12: Most Women's World Cup titles | D12: USA | E12: USA | F12: Team | G12: 4 | H12: titles | I12: 4 | J12: 2019 | K12: ='Notes & Sources'!$B$3-J12 -> 7 | L12: FIFA Women's World Cup | M12: Stable – unchanged since set
A13: 12 | B13: World Cup | C13: Most Women's World Cup goals | D13: Marta | E13: Brazil | F13: W | G13: 17 | H13: goals | I13: 17 | J13: 2019 | K13: ='Notes & Sources'!$B$3-J13 -> 7 | L13: FIFA Women's World Cup | M13: Stable – unchanged since set
A14: 13 | B14: International | C14: Most men's international goals | D14: Cristiano Ronaldo | E14: Portugal | F14: M | G14: 146 | H14: goals | I14: 146 | J14: 2026 | K14: ='Notes & Sources'!$B$3-J14 -> 0 | L14: Internationals | M14: Checked online Sept 2026 | N14: Active – value as of 24 Sept 2026
A15: 14 | B15: International | C15: Most men's international caps | D15: Cristiano Ronaldo | E15: Portugal | F15: M | G15: 234 | H15: caps | I15: 234 | J15: 2026 | K15: ='Notes & Sources'!$B$3-J15 -> 0 | L15: Internationals | M15: Checked online Sept 2026 | N15: Active – value as of 24 Sept 2026 (UEFA)
A16: 15 | B16: International | C16: Scored in most consecutive calendar years | D16: Cristiano Ronaldo | E16: Portugal | F16: M | G16: 23 | H16: years | I16: 23 | J16: 2026 | K16: ='Notes & Sources'!$B$3-J16 -> 0 | L16: Internationals | M16: Checked online Sept 2026 | N16: Every year 2004–2026
A17: 16 | B17: International | C17: Most goals in one international match | D17: Archie Thompson | E17: Australia | F17: M | G17: 13 | H17: goals | I17: 13 | J17: 2001 | K17: ='Notes & Sources'!$B$3-J17 -> 25 | L17: Internationals | M17: Stable – unchanged since set | N17: vs American Samoa
A18: 17 | B18: International | C18: Biggest international win (margin) | D18: Australia | E18: Australia | F18: Team | G18: 31 | H18: goals | I18: 31–0 | J18: 2001 | K18: ='Notes & Sources'!$B$3-J18 -> 25 | L18: Internationals | M18: Stable – unchanged since set | N18: vs American Samoa
A19: 18 | B19: International | C19: Most women's international goals | D19: Christine Sinclair | E19: Canada | F19: W | G19: 190 | H19: goals | I19: 190 | J19: 2023 | K19: ='Notes & Sources'!$B$3-J19 -> 3 | L19: Internationals | M19: Stable – unchanged since set
A20: 19 | B20: International | C20: Most women's international caps | D20: Kristine Lilly | E20: USA | F20: W | G20: 354 | H20: caps | I20: 354 | J20: 2010 | K20: ='Notes & Sources'!$B$3-J20 -> 16 | L20: Internationals | M20: Stable – unchanged since set
A21: 20 | B21: International | C21: Most European Championship titles | D21: Spain | E21: Spain | F21: Team | G21: 4 | H21: titles | I21: 4 | J21: 2024 | K21: ='Notes & Sources'!$B$3-J21 -> 2 | L21: UEFA Euro | M21: Stable – unchanged since set
A22: 21 | B22: International | C22: Most European Championship goals | D22: Cristiano Ronaldo | E22: Portugal | F22: M | G22: 14 | H22: goals | I22: 14 | J22: 2021 | K22: ='Notes & Sources'!$B$3-J22 -> 5 | L22: UEFA Euro | M22: Stable – unchanged since set
A23: 22 | B23: International | C23: Most goals at a single Euro | D23: Michel Platini | E23: France | F23: M | G23: 9 | H23: goals | I23: 9 | J23: 1984 | K23: ='Notes & Sources'!$B$3-J23 -> 42 | L23: UEFA Euro | M23: Stable – unchanged since set
A24: 23 | B24: International | C24: Youngest Euro goalscorer | D24: Lamine Yamal | E24: Spain | F24: M | G24: 16.99 | H24: years | I24: 16 y 362 d | J24: 2024 | K24: ='Notes & Sources'!$B$3-J24 -> 2 | L24: UEFA Euro | M24: Stable – unchanged since set
A25: 24 | B25: International | C25: Most Copa América titles | D25: Argentina | E25: Argentina | F25: Team | G25: 16 | H25: titles | I25: 16 | J25: 2024 | K25: ='Notes & Sources'!$B$3-J25 -> 2 | L25: Copa América | M25: Stable – unchanged since set
A26: 25 | B26: Champions League | C26: Most European Cup / UCL titles (club) | D26: Real Madrid | E26: Real Madrid | F26: Team | G26: 15 | H26: titles | I26: 15 | J26: 2024 | K26: ='Notes & Sources'!$B$3-J26 -> 2 | L26: UEFA Champions League | M26: Checked online Sept 2026 | N26: PSG won 2025 and 2026
A27: 26 | B27: Champions League | C27: Most European Cup titles (player) | D27: Paco Gento | E27: Real Madrid | F27: M | G27: 6 | H27: titles | I27: 6 | J27: 1966 | K27: ='Notes & Sources'!$B$3-J27 -> 60 | L27: UEFA Champions League | M27: Stable – unchanged since set | N27: Equalled by Modrić, Kroos, Carvajal, Nacho in 2024
A28: 27 | B28: Champions League | C28: Most Champions League goals | D28: Cristiano Ronaldo | E28: Portugal | F28: M | G28: 140 | H28: goals | I28: 140 | J28: 2022 | K28: ='Notes & Sources'!$B$3-J28 -> 4 | L28: UEFA Champions League | M28: Stable – unchanged since set | N28: Left European football in 2022
A29: 28 | B29: Champions League | C29: Most Champions League appearances | D29: Cristiano Ronaldo | E29: Portugal | F29: M | G29: 183 | H29: matches | I29: 183 | J29: 2022 | K29: ='Notes & Sources'!$B$3-J29 -> 4 | L29: UEFA Champions League | M29: Stable – unchanged since set
A30: 29 | B30: Champions League | C30: Most Champions League goals for one club | D30: Lionel Messi | E30: Barcelona | F30: M | G30: 120 | H30: goals | I30: 120 | J30: 2021 | K30: ='Notes & Sources'!$B$3-J30 -> 5 | L30: UEFA Champions League | M30: Stable – unchanged since set
A31: 30 | B31: Champions League | C31: Most goals by a player in one UCL match | D31: Messi / Luiz Adriano / Haaland | E31: ARG / BRA / NOR | F31: M | G31: 5 | H31: goals | I31: 5 | J31: 2023 | K31: ='Notes & Sources'!$B$3-J31 -> 3 | L31: UEFA Champions League | M31: Stable – unchanged since set | N31: Shared; year = most recent
A32: 31 | B32: Champions League | C32: Biggest win in a European Cup / UCL final | D32: Paris Saint-Germain | E32: PSG | F32: Team | G32: 5 | H32: goals | I32: 5–0 v Inter | J32: 2025 | K32: ='Notes & Sources'!$B$3-J32 -> 1 | L32: UEFA Champions League | M32: Checked online Sept 2026
A33: 32 | B33: Premier League | C33: Most Premier League goals | D33: Alan Shearer | E33: England | F33: M | G33: 260 | H33: goals | I33: 260 | J33: 2006 | K33: ='Notes & Sources'!$B$3-J33 -> 20 | L33: Premier League | M33: Stable – unchanged since set
A34: 33 | B34: Premier League | C34: Most Premier League assists | D34: Ryan Giggs | E34: Wales | F34: M | G34: 162 | H34: assists | I34: 162 | J34: 2014 | K34: ='Notes & Sources'!$B$3-J34 -> 12 | L34: Premier League | M34: Stable – unchanged since set
A35: 34 | B35: Premier League | C35: Most Premier League clean sheets | D35: Petr Čech | E35: Czechia | F35: M | G35: 202 | H35: clean sheets | I35: 202 | J35: 2019 | K35: ='Notes & Sources'!$B$3-J35 -> 7 | L35: Premier League | M35: Stable – unchanged since set
A36: 35 | B36: Premier League | C36: Most Premier League titles (club) | D36: Manchester United | E36: Man United | F36: Team | G36: 13 | H36: titles | I36: 13 | J36: 2013 | K36: ='Notes & Sources'!$B$3-J36 -> 13 | L36: Premier League | M36: Checked online Sept 2026
A37: 36 | B37: Premier League | C37: Most English top-flight titles | D37: Manchester United / Liverpool | E37: Man United / Liverpool | F37: Team | G37: 20 | H37: titles | I37: 20 | J37: 2025 | K37: ='Notes & Sources'!$B$3-J37 -> 1 | L37: English top flight | M37: Checked online Sept 2026 | N37: Arsenal won 2025–26 (14th)
A38: 37 | B38: Premier League | C38: Most Premier League titles (player) | D38: Ryan Giggs | E38: Wales | F38: M | G38: 13 | H38: titles | I38: 13 | J38: 2013 | K38: ='Notes & Sources'!$B$3-J38 -> 13 | L38: Premier League | M38: Stable – unchanged since set
A39: 38 | B39: Premier League | C39: Most points in a Premier League season | D39: Manchester City | E39: Man City | F39: Team | G39: 100 | H39: points | I39: 100 | J39: 2018 | K39: ='Notes & Sources'!$B$3-J39 -> 8 | L39: Premier League | M39: Stable – unchanged since set
A40: 39 | B40: Premier League | C40: Longest Premier League unbeaten run | D40: Arsenal | E40: Arsenal | F40: Team | G40: 49 | H40: matches | I40: 49 | J40: 2004 | K40: ='Notes & Sources'!$B$3-J40 -> 22 | L40: Premier League | M40: Stable – unchanged since set | N40: 'The Invincibles'
...

Sheet By Category
A1: Category | B1: Records | C1: Checked online | D1: Oldest (year set) | E1: Newest (year set)
A2: World Cup | B2: =COUNTIF('Football Records'!B:B,A2) -> 12 | C2: =COUNTIFS('Football Records'!B:B,A2,'Football Records'!M:M,"Checked online Sept 2026") -> 6 | D2: =_xlfn.MINIFS('Football Records'!J:J,'Football Records'!B:B,A2) -> 1938 | E2: =_xlfn.MAXIFS('Football Records'!J:J,'Football Records'!B:B,A2) -> 2026
A3: International | B3: =COUNTIF('Football Records'!B:B,A3) -> 12 | C3: =COUNTIFS('Football Records'!B:B,A3,'Football Records'!M:M,"Checked online Sept 2026") -> 3 | D3: =_xlfn.MINIFS('Football Records'!J:J,'Football Records'!B:B,A3) -> 1984 | E3: =_xlfn.MAXIFS('Football Records'!J:J,'Football Records'!B:B,A3) -> 2026
A4: Champions League | B4: =COUNTIF('Football Records'!B:B,A4) -> 7 | C4: =COUNTIFS('Football Records'!B:B,A4,'Football Records'!M:M,"Checked online Sept 2026") -> 2 | D4: =_xlfn.MINIFS('Football Records'!J:J,'Football Records'!B:B,A4) -> 1966 | E4: =_xlfn.MAXIFS('Football Records'!J:J,'Football Records'!B:B,A4) -> 2025
A5: Premier League | B5: =COUNTIF('Football Records'!B:B,A5) -> 15 | C5: =COUNTIFS('Football Records'!B:B,A5,'Football Records'!M:M,"Checked online Sept 2026") -> 2 | D5: =_xlfn.MINIFS('Football Records'!J:J,'Football Records'!B:B,A5) -> 2004 | E5: =_xlfn.MAXIFS('Football Records'!J:J,'Football Records'!B:B,A5) -> 2025
A6: Top leagues | B6: =COUNTIF('Football Records'!B:B,A6) -> 7 | C6: =COUNTIFS('Football Records'!B:B,A6,'Football Records'!M:M,"Checked online Sept 2026") -> 2 | D6: =_xlfn.MINIFS('Football Records'!J:J,'Football Records'!B:B,A6) -> 1954 | E6: =_xlfn.MAXIFS('Football Records'!J:J,'Football Records'!B:B,A6) -> 2026
A7: Career & awards | B7: =COUNTIF('Football Records'!B:B,A7) -> 7 | C7: =COUNTIFS('Football Records'!B:B,A7,'Football Records'!M:M,"Checked online Sept 2026") -> 2 | D7: =_xlfn.MINIFS('Football Records'!J:J,'Football Records'!B:B,A7) -> 2012 | E7: =_xlfn.MAXIFS('Football Records'!J:J,'Football Records'!B:B,A7) -> 2026
A8: Transfers & crowds | B8: =COUNTIF('Football Records'!B:B,A8) -> 4 | C8: =COUNTIFS('Football Records'!B:B,A8,'Football Records'!M:M,"Checked online Sept 2026") -> 2 | D8: =_xlfn.MINIFS('Football Records'!J:J,'Football Records'!B:B,A8) -> 1950 | E8: =_xlfn.MAXIFS('Football Records'!J:J,'Football Records'!B:B,A8) -> 2025
A9: Crazy & historic | B9: =COUNTIF('Football Records'!B:B,A9) -> 31 | C9: =COUNTIFS('Football Records'!B:B,A9,'Football Records'!M:M,"Checked online Sept 2026") -> 8 | D9: =_xlfn.MINIFS('Football Records'!J:J,'Football Records'!B:B,A9) -> 1857 | E9: =_xlfn.MAXIFS('Football Records'!J:J,'Football Records'!B:B,A9) -> 2024
A10: Players – all-time | B10: =COUNTIF('Football Records'!B:B,A10) -> 27 | C10: =COUNTIFS('Football Records'!B:B,A10,'Football Records'!M:M,"Checked online Sept 2026") -> 1 | D10: =_xlfn.MINIFS('Football Records'!J:J,'Football Records'!B:B,A10) -> 1931 | E10: =_xlfn.MAXIFS('Football Records'!J:J,'Football Records'!B:B,A10) -> 2026
A11: Ages & careers | B11: =COUNTIF('Football Records'!B:B,A11) -> 11 | C11: =COUNTIFS('Football Records'!B:B,A11,'Football Records'!M:M,"Checked online Sept 2026") -> 0 | D11: =_xlfn.MINIFS('Football Records'!J:J,'Football Records'!B:B,A11) -> 2000 | E11: =_xlfn.MAXIFS('Football Records'!J:J,'Football Records'!B:B,A11) -> 2026
A12: Goalkeepers | B12: =COUNTIF('Football Records'!B:B,A12) -> 7 | C12: =COUNTIFS('Football Records'!B:B,A12,'Football Records'!M:M,"Checked online Sept 2026") -> 0 | D12: =_xlfn.MINIFS('Football Records'!J:J,'Football Records'!B:B,A12) -> 1974 | E12: =_xlfn.MAXIFS('Football Records'!J:J,'Football Records'!B:B,A12) -> 2016
A13: Coaches | B13: =COUNTIF('Football Records'!B:B,A13) -> 5 | C13: =COUNTIFS('Football Records'!B:B,A13,'Football Records'!M:M,"Checked online Sept 2026") -> 0 | D13: =_xlfn.MINIFS('Football Records'!J:J,'Football Records'!B:B,A13) -> 1940 | E13: =_xlfn.MAXIFS('Football Records'!J:J,'Football Records'!B:B,A13) -> 2013
A14: Clubs & teams | B14: =COUNTIF('Football Records'!B:B,A14) -> 15 | C14: =COUNTIFS('Football Records'!B:B,A14,'Football Records'!M:M,"Checked online Sept 2026") -> 0 | D14: =_xlfn.MINIFS('Football Records'!J:J,'Football Records'!B:B,A14) -> 1885 | E14: =_xlfn.MAXIFS('Football Records'!J:J,'Football Records'!B:B,A14) -> 2025
A15: Total | B15: =SUM(B2:B14) -> 160 | C15: =SUM(C2:C14) -> 28 | D15: =MIN(D2:D14) -> 1857 | E15: =MAX(E2:E14) -> 2026

Sheet Notes & Sources
A1: Sportrankle – Football Records (state: 25 September 2026)
A3: Reference year (edit) | B3: 2026
A5: Value | B5: Numeric value for sorting. Times are stored in seconds (see 'Display'), ages in years, fees in € million.
A6: Years standing | B6: Reference year minus Year set. Change B3 to update.
A7: Check: Checked online Sept 2026 | B7: Holder and value confirmed on 25 Sept 2026 against FIFA, UEFA, league sites, Guinness World Records or major outlets (Sky Sports, ESPN, AP, Olympics.com, Wikipedia records lists).
A8: Check: Stable – unchanged since set | B8: Historic records with no change as of Sept 2026 (holder retired, competition ended, or nobody close).
A9: Active players | B9: Ronaldo's international goals, caps and career goals keep moving – values are frozen at 24 Sept 2026.
A10: Left out on purpose | B10: Records whose current value could not be confirmed for Sept 2026, e.g. La Liga/Serie A/Ligue 1 title counts (2025–26 champions not confirmed), Messi's trophy count, Premier League appearance record (Milner still active), Unai Simón's final World Cup clean-sheet minutes, final 2026 World Cup goal and attendance totals.
A11: Comparability | B11: Units differ between rows – rank within the same unit, or use 'Year set' / 'Years standing' across all records.
