Workbook

Sheet Daten
A1: Spieler | B1: Geburtsdatum (Datum) | C1: Grösse (cm) | D1: Gewicht (kg) | E1: Draft-Jahr (Jahr) | F1: Draft-Position (Overall-Pick) | G1: Alter beim NFL-Debüt (Jahre) | H1: Playoff-Spiele Karriere (Spiele) | I1: Saisons im aktuellen Team (Saisons) | J1: Pro-Bowl-Nominierungen (Anzahl) | K1: First-Team All-Pro (Anzahl) | L1: Super-Bowl-Teilnahmen (Anzahl) | M1: Rückennummer (Nr.) | N1: Ø Jahresgehalt aktueller Vertrag (Mio. USD) | O1: Vertrag läuft bis (Saison) | P1: Einwohner Geburtsort (Tsd.) | Q1: HILFSSPALTE: Team (Sept. 2026) | R1: HILFSSPALTE: Position | S1: HILFSSPALTE: Erste Saison beim aktuellen Team | T1: HILFSSPALTE: Geburtsort | U1: HILFSSPALTE: Anzahl NFL-Teams (Karriere) | V1: Anmerkung
A2: Patrick Mahomes | B2: 34959 | C2: 188 | D2: 102 | E2: 2017 | F2: 10 | G2: =ROUND((DATE(E2,9,1)-B2)/365.25,2) -> 21.96 | H2: 21 | I2: =$B$103-S2+1 -> 10 | J2: 6 | K2: 2 | L2: 5 | M2: 15 | N2: 45 | O2: 2031 | P2: 108 | Q2: Kansas City Chiefs | R2: QB | S2: 2017 | T2: Tyler, TX | U2: 1 | V2: 10-Jahres-Vertrag (450 Mio., 2020). 3 Super-Bowl-Siege (LIV, LVII, LVIII). Pro Bowls 2018–2023.
A3: Josh Allen | B3: 35206 | C3: 196 | D3: 107 | E3: 2018 | F3: 7 | G3: =ROUND((DATE(E3,9,1)-B3)/365.25,2) -> 22.28 | H3: 15 | I3: =$B$103-S3+1 -> 9 | J3: 4 | K3: 1 | L3: 0 | M3: 17 | N3: 55 | O3: 2030 | P3: 8 | Q3: Buffalo Bills | R3: QB | S3: 2018 | T3: Firebaugh, CA | U3: 1 | V3: MVP 2024. Vertrag 6 J./330 Mio. (2025). Kleinste Heimatstadt der Liste.
A4: Lamar Jackson | B4: 35437 | C4: 188 | D4: 98 | E4: 2018 | F4: 32 | G4: =ROUND((DATE(E4,9,1)-B4)/365.25,2) -> 21.65 | H4: 9 | I4: =$B$103-S4+1 -> 9 | J4: 4 | K4: 3 | L4: 0 | M4: 8 | N4: 52 | O4: 2027 | P4: 112 | Q4: Baltimore Ravens | R4: QB | S4: 2018 | T4: Pompano Beach, FL | U4: 1 | V4: Zweifacher MVP (2019, 2023). Letzter Pick der 1. Runde 2018.
A5: Joe Burrow | B5: 35409 | C5: 193 | D5: 100 | E5: 2020 | F5: 1 | G5: =ROUND((DATE(E5,9,1)-B5)/365.25,2) -> 23.73 | H5: 7 | I5: =$B$103-S5+1 -> 7 | J5: 2 | K5: 0 | L5: 1 | M5: 9 | N5: 55 | O5: 2029 | P5: 66 | Q5: Cincinnati Bengals | R5: QB | S5: 2020 | T5: Ames, IA | U5: 1 | V5: Nr.-1-Pick 2020. Super Bowl LVI (Niederlage). Geboren in Ames, aufgewachsen in Athens, OH.
A6: Jalen Hurts | B6: 36014 | C6: 185 | D6: 101 | E6: 2020 | F6: 53 | G6: =ROUND((DATE(E6,9,1)-B6)/365.25,2) -> 22.07 | H6: 10 | I6: =$B$103-S6+1 -> 7 | J6: 2 | K6: 0 | L6: 2 | M6: 1 | N6: 51 | O6: 2028 | P6: 2314 | Q6: Philadelphia Eagles | R6: QB | S6: 2020 | T6: Houston, TX | U6: 1 | V6: Super-Bowl-LIX-MVP. Zweitrundenpick 2020. Grösste Heimatstadt (Houston).
A7: Justin Herbert | B7: 35864 | C7: 198 | D7: 107 | E7: 2020 | F7: 6 | G7: =ROUND((DATE(E7,9,1)-B7)/365.25,2) -> 22.48 | H7: 3 | I7: =$B$103-S7+1 -> 7 | J7: 1 | K7: 0 | L7: 0 | M7: 10 | N7: 52.5 | O7: 2029 | P7: 178 | Q7: Los Angeles Chargers | R7: QB | S7: 2020 | T7: Eugene, OR | U7: 1 | V7: Grösster Spieler der Liste (198 cm). Offensive Rookie of the Year 2020.
A8: C.J. Stroud | B8: 37167 | C8: 191 | D8: 98 | E8: 2023 | F8: 2 | G8: =ROUND((DATE(E8,9,1)-B8)/365.25,2) -> 21.91 | H8: 6 | I8: =$B$103-S8+1 -> 4 | J8: 1 | K8: 0 | L8: 0 | M8: 7 | N8: 9.08 | O8: 2026 | P8: 174 | Q8: Houston Texans | R8: QB | S8: 2023 | T8: Rancho Cucamonga, CA | U8: 1 | V8: Rookie-Vertrag (4 J./36,3 Mio.), Fifth-Year-Option 2027 möglich – Verlängerung 2026 vor Livegang prüfen.
A9: Jayden Daniels | B9: 36878 | C9: 193 | D9: 95 | E9: 2024 | F9: 2 | G9: =ROUND((DATE(E9,9,1)-B9)/365.25,2) -> 23.7 | H9: 3 | I9: =$B$103-S9+1 -> 3 | J9: 1 | K9: 0 | L9: 0 | M9: 5 | N9: 9.44 | O9: 2027 | P9: 222 | Q9: Washington Commanders | R9: QB | S9: 2024 | T9: San Bernardino, CA | U9: 1 | V9: Heisman 2023, Offensive Rookie of the Year 2024. Rookie-Vertrag 4 J./37,7 Mio.
A10: Drake Maye | B10: 37498 | C10: 193 | D10: 102 | E10: 2024 | F10: 3 | G10: =ROUND((DATE(E10,9,1)-B10)/365.25,2) -> 22.01 | H10: 4 | I10: =$B$103-S10+1 -> 3 | J10: 0 | K10: 0 | L10: 1 | M10: 10 | N10: 9.16 | O10: 2027 | P10: 897 | Q10: New England Patriots | R10: QB | S10: 2024 | T10: Charlotte, NC | U10: 1 | V10: Super Bowl LX (Niederlage). Pro-Bowl-Stand bis Saison 2024 = 0 – Saison 2025 vor Livegang ergänzen. Jüngster QB der Liste.
A11: Caleb Williams | B11: 37213 | C11: 185 | D11: 97 | E11: 2024 | F11: 1 | G11: =ROUND((DATE(E11,9,1)-B11)/365.25,2) -> 22.79 | H11: 2 | I11: =$B$103-S11+1 -> 3 | J11: 0 | K11: 0 | L11: 0 | M11: 18 | N11: 9.87 | O11: 2027 | P11: 678 | Q11: Chicago Bears | R11: QB | S11: 2024 | T11: Washington, D.C. | U11: 1 | V11: Nr.-1-Pick 2024, Heisman 2022. Erster Playoff-Sieg der Bears seit 2011 (Jan. 2026).
A12: Jordan Love | B12: 36101 | C12: 193 | D12: 99 | E12: 2020 | F12: 26 | G12: =ROUND((DATE(E12,9,1)-B12)/365.25,2) -> 21.83 | H12: 4 | I12: =$B$103-S12+1 -> 7 | J12: 0 | K12: 0 | L12: 0 | M12: 10 | N12: 55 | O12: 2028 | P12: 413 | Q12: Green Bay Packers | R12: QB | S12: 2020 | T12: Bakersfield, CA | U12: 1 | V12: Drei Jahre Backup hinter Rodgers, Starter seit 2023. Vertrag 4 J./220 Mio. (2024).
A13: Brock Purdy | B13: 36521 | C13: 185 | D13: 100 | E13: 2022 | F13: 262 | G13: =ROUND((DATE(E13,9,1)-B13)/365.25,2) -> 22.68 | H13: 8 | I13: =$B$103-S13+1 -> 5 | J13: 1 | K13: 0 | L13: 1 | M13: 13 | N13: 53 | O13: 2030 | P13: 76 | Q13: San Francisco 49ers | R13: QB | S13: 2022 | T13: Queen Creek, AZ | U13: 1 | V13: 'Mr. Irrelevant' – letzter Pick des Drafts 2022 (Nr. 262). Vertrag 5 J./265 Mio. (2025).
... A101: Brian Branch | B101: 37247 | C101: 183 | D101: 86 | E101: 2023 | F101: 45 | G101: =ROUND((DATE(E101,9,1)-B101)/365.25,2) -> 21.69 | H101: 4 | I101: =$B$103-S101+1 -> 4 | J101: 1 | K101: 0 | L101: 0 | M101: 32 | N101: 2 | O101: 2026 | P101: 8 | Q101: Detroit Lions | R101: S | S101: 2023 | T101: Tyrone, GA | U101: 1 | V101: Zweitrundenpick. Pro Bowl 2024. Rookie-Vertrag läuft 2026 aus.
A103: Referenzjahr / Stichtag (für Formeln) | B103: 2026
A104: Graue Spalten = Hilfsspalten (Rohdaten für Formeln), nicht als Attribut im Spiel verwenden. Formelspalten rechnen live aus den Hilfsspalten.
A105: Werte mit dem Vermerk 'vor Livegang prüfen' in der Anmerkung/Kategorien-Tabelle vor Veröffentlichung gegenprüfen.

Sheet Ränge
A1: Spieler | B1: Geburtsdatum | C1: Grösse | D1: Gewicht | E1: Draft-Jahr | F1: Draft-Position | G1: Alter beim NFL-Debüt | H1: Playoff-Spiele Karriere | I1: Saisons im aktuellen Team | J1: Pro-Bowl-Nominierungen | K1: First-Team All-Pro | L1: Super-Bowl-Teilnahmen | M1: Rückennummer | N1: Ø Jahresgehalt aktueller Vertrag | O1: Vertrag läuft bis | P1: Einwohner Geburtsort | Q1: Anzahl Top-3-Ränge | R1: Anzahl Rang 1
A2: =Daten!A2 -> Patrick Mahomes | B2: =RANK(Daten!B2,Daten!B$2:B$101,1) -> 15 | C2: =RANK(Daten!C2,Daten!C$2:C$101,0) -> 53 | D2: =RANK(Daten!D2,Daten!D$2:D$101,0) -> 38 | E2: =RANK(Daten!E2,Daten!E$2:E$101,1) -> 11 | F2: =RANK(Daten!F2,Daten!F$2:F$101,1) -> 49 | G2: =RANK(Daten!G2,Daten!G$2:G$101,1) -> 44 | H2: =RANK(Daten!H2,Daten!H$2:H$101,0) -> 2 | I2: =RANK(Daten!I2,Daten!I$2:I$101,0) -> 5 | J2: =RANK(Daten!J2,Daten!J$2:J$101,0) -> 5 | K2: =RANK(Daten!K2,Daten!K$2:K$101,0) -> 10 | L2: =RANK(Daten!L2,Daten!L$2:L$101,0) -> 1 | M2: =RANK(Daten!M2,Daten!M$2:M$101,1) -> 50 | N2: =RANK(Daten!N2,Daten!N$2:N$101,0) -> 14 | O2: =RANK(Daten!O2,Daten!O$2:O$101,0) -> 1 | P2: =RANK(Daten!P2,Daten!P$2:P$101,0) -> 39 | Q2: =COUNTIF(B2:P2,"<=3") -> 3 | R2: =COUNTIF(B2:P2,1) -> 2
A3: =Daten!A3 -> Josh Allen | B3: =RANK(Daten!B3,Daten!B$2:B$101,1) -> 18 | C3: =RANK(Daten!C3,Daten!C$2:C$101,0) -> 8 | D3: =RANK(Daten!D3,Daten!D$2:D$101,0) -> 29 | E3: =RANK(Daten!E3,Daten!E$2:E$101,1) -> 16 | F3: =RANK(Daten!F3,Daten!F$2:F$101,1) -> 36 | G3: =RANK(Daten!G3,Daten!G$2:G$101,1) -> 66 | H3: =RANK(Daten!H3,Daten!H$2:H$101,0) -> 4 | I3: =RANK(Daten!I3,Daten!I$2:I$101,0) -> 9 | J3: =RANK(Daten!J3,Daten!J$2:J$101,0) -> 13 | K3: =RANK(Daten!K3,Daten!K$2:K$101,0) -> 22 | L3: =RANK(Daten!L3,Daten!L$2:L$101,0) -> 30 | M3: =RANK(Daten!M3,Daten!M$2:M$101,1) -> 56 | N3: =RANK(Daten!N3,Daten!N$2:N$101,0) -> 2 | O3: =RANK(Daten!O3,Daten!O$2:O$101,0) -> 2 | P3: =RANK(Daten!P3,Daten!P$2:P$101,0) -> 82 | Q3: =COUNTIF(B3:P3,"<=3") -> 2 | R3: =COUNTIF(B3:P3,1) -> 0
A4: =Daten!A4 -> Lamar Jackson | B4: =RANK(Daten!B4,Daten!B$2:B$101,1) -> 23 | C4: =RANK(Daten!C4,Daten!C$2:C$101,0) -> 53 | D4: =RANK(Daten!D4,Daten!D$2:D$101,0) -> 54 | E4: =RANK(Daten!E4,Daten!E$2:E$101,1) -> 16 | F4: =RANK(Daten!F4,Daten!F$2:F$101,1) -> 73 | G4: =RANK(Daten!G4,Daten!G$2:G$101,1) -> 25 | H4: =RANK(Daten!H4,Daten!H$2:H$101,0) -> 18 | I4: =RANK(Daten!I4,Daten!I$2:I$101,0) -> 9 | J4: =RANK(Daten!J4,Daten!J$2:J$101,0) -> 13 | K4: =RANK(Daten!K4,Daten!K$2:K$101,0) -> 3 | L4: =RANK(Daten!L4,Daten!L$2:L$101,0) -> 30 | M4: =RANK(Daten!M4,Daten!M$2:M$101,1) -> 28 | N4: =RANK(Daten!N4,Daten!N$2:N$101,0) -> 10 | O4: =RANK(Daten!O4,Daten!O$2:O$101,0) -> 54 | P4: =RANK(Daten!P4,Daten!P$2:P$101,0) -> 37 | Q4: =COUNTIF(B4:P4,"<=3") -> 1 | R4: =COUNTIF(B4:P4,1) -> 0
A5: =Daten!A5 -> Joe Burrow | B5: =RANK(Daten!B5,Daten!B$2:B$101,1) -> 22 | C5: =RANK(Daten!C5,Daten!C$2:C$101,0) -> 18 | D5: =RANK(Daten!D5,Daten!D$2:D$101,0) -> 44 | E5: =RANK(Daten!E5,Daten!E$2:E$101,1) -> 34 | F5: =RANK(Daten!F5,Daten!F$2:F$101,1) -> 1 | G5: =RANK(Daten!G5,Daten!G$2:G$101,1) -> 95 | H5: =RANK(Daten!H5,Daten!H$2:H$101,0) -> 24 | I5: =RANK(Daten!I5,Daten!I$2:I$101,0) -> 19 | J5: =RANK(Daten!J5,Daten!J$2:J$101,0) -> 37 | K5: =RANK(Daten!K5,Daten!K$2:K$101,0) -> 37 | L5: =RANK(Daten!L5,Daten!L$2:L$101,0) -> 11 | M5: =RANK(Daten!M5,Daten!M$2:M$101,1) -> 31 | N5: =RANK(Daten!N5,Daten!N$2:N$101,0) -> 2 | O5: =RANK(Daten!O5,Daten!O$2:O$101,0) -> 8 | P5: =RANK(Daten!P5,Daten!P$2:P$101,0) -> 48 | Q5: =COUNTIF(B5:P5,"<=3") -> 2 | R5: =COUNTIF(B5:P5,1) -> 1
A6: =Daten!A6 -> Jalen Hurts | B6: =RANK(Daten!B6,Daten!B$2:B$101,1) -> 37 | C6: =RANK(Daten!C6,Daten!C$2:C$101,0) -> 63 | D6: =RANK(Daten!D6,Daten!D$2:D$101,0) -> 43 | E6: =RANK(Daten!E6,Daten!E$2:E$101,1) -> 34 | F6: =RANK(Daten!F6,Daten!F$2:F$101,1) -> 84 | G6: =RANK(Daten!G6,Daten!G$2:G$101,1) -> 51 | H6: =RANK(Daten!H6,Daten!H$2:H$101,0) -> 13 | I6: =RANK(Daten!I6,Daten!I$2:I$101,0) -> 19 | J6: =RANK(Daten!J6,Daten!J$2:J$101,0) -> 37 | K6: =RANK(Daten!K6,Daten!K$2:K$101,0) -> 37 | L6: =RANK(Daten!L6,Daten!L$2:L$101,0) -> 5 | M6: =RANK(Daten!M6,Daten!M$2:M$101,1) -> 2 | N6: =RANK(Daten!N6,Daten!N$2:N$101,0) -> 11 | O6: =RANK(Daten!O6,Daten!O$2:O$101,0) -> 22 | P6: =RANK(Daten!P6,Daten!P$2:P$101,0) -> 1 | Q6: =COUNTIF(B6:P6,"<=3") -> 2 | R6: =COUNTIF(B6:P6,1) -> 1
A7: =Daten!A7 -> Justin Herbert | B7: =RANK(Daten!B7,Daten!B$2:B$101,1) -> 36 | C7: =RANK(Daten!C7,Daten!C$2:C$101,0) -> 2 | D7: =RANK(Daten!D7,Daten!D$2:D$101,0) -> 29 | E7: =RANK(Daten!E7,Daten!E$2:E$101,1) -> 34 | F7: =RANK(Daten!F7,Daten!F$2:F$101,1) -> 31 | G7: =RANK(Daten!G7,Daten!G$2:G$101,1) -> 73 | H7: =RANK(Daten!H7,Daten!H$2:H$101,0) -> 55 | I7: =RANK(Daten!I7,Daten!I$2:I$101,0) -> 19 | J7: =RANK(Daten!J7,Daten!J$2:J$101,0) -> 48 | K7: =RANK(Daten!K7,Daten!K$2:K$101,0) -> 37 | L7: =RANK(Daten!L7,Daten!L$2:L$101,0) -> 30 | M7: =RANK(Daten!M7,Daten!M$2:M$101,1) -> 37 | N7: =RANK(Daten!N7,Daten!N$2:N$101,0) -> 9 | O7: =RANK(Daten!O7,Daten!O$2:O$101,0) -> 8 | P7: =RANK(Daten!P7,Daten!P$2:P$101,0) -> 33 | Q7: =COUNTIF(B7:P7,"<=3") -> 1 | R7: =COUNTIF(B7:P7,1) -> 0
A8: =Daten!A8 -> C.J. Stroud | B8: =RANK(Daten!B8,Daten!B$2:B$101,1) -> 77 | C8: =RANK(Daten!C8,Daten!C$2:C$101,0) -> 37 | D8: =RANK(Daten!D8,Daten!D$2:D$101,0) -> 54 | E8: =RANK(Daten!E8,Daten!E$2:E$101,1) -> 66 | F8: =RANK(Daten!F8,Daten!F$2:F$101,1) -> 12 | G8: =RANK(Daten!G8,Daten!G$2:G$101,1) -> 40 | H8: =RANK(Daten!H8,Daten!H$2:H$101,0) -> 29 | I8: =RANK(Daten!I8,Daten!I$2:I$101,0) -> 56 | J8: =RANK(Daten!J8,Daten!J$2:J$101,0) -> 48 | K8: =RANK(Daten!K8,Daten!K$2:K$101,0) -> 37 | L8: =RANK(Daten!L8,Daten!L$2:L$101,0) -> 30 | M8: =RANK(Daten!M8,Daten!M$2:M$101,1) -> 25 | N8: =RANK(Daten!N8,Daten!N$2:N$101,0) -> 72 | O8: =RANK(Daten!O8,Daten!O$2:O$101,0) -> 76 | P8: =RANK(Daten!P8,Daten!P$2:P$101,0) -> 34 | Q8: =COUNTIF(B8:P8,"<=3") -> 0 | R8: =COUNTIF(B8:P8,1) -> 0
A9: =Daten!A9 -> Jayden Daniels | B9: =RANK(Daten!B9,Daten!B$2:B$101,1) -> 68 | C9: =RANK(Daten!C9,Daten!C$2:C$101,0) -> 18 | D9: =RANK(Daten!D9,Daten!D$2:D$101,0) -> 71 | E9: =RANK(Daten!E9,Daten!E$2:E$101,1) -> 79 | F9: =RANK(Daten!F9,Daten!F$2:F$101,1) -> 12 | G9: =RANK(Daten!G9,Daten!G$2:G$101,1) -> 94 | H9: =RANK(Daten!H9,Daten!H$2:H$101,0) -> 55 | I9: =RANK(Daten!I9,Daten!I$2:I$101,0) -> 70 | J9: =RANK(Daten!J9,Daten!J$2:J$101,0) -> 48 | K9: =RANK(Daten!K9,Daten!K$2:K$101,0) -> 37 | L9: =RANK(Daten!L9,Daten!L$2:L$101,0) -> 30 | M9: =RANK(Daten!M9,Daten!M$2:M$101,1) -> 18 | N9: =RANK(Daten!N9,Daten!N$2:N$101,0) -> 70 | O9: =RANK(Daten!O9,Daten!O$2:O$101,0) -> 54 | P9: =RANK(Daten!P9,Daten!P$2:P$101,0) -> 28 | Q9: =COUNTIF(B9:P9,"<=3") -> 0 | R9: =COUNTIF(B9:P9,1) -> 0
A10: =Daten!A10 -> Drake Maye | B10: =RANK(Daten!B10,Daten!B$2:B$101,1) -> 89 | C10: =RANK(Daten!C10,Daten!C$2:C$101,0) -> 18 | D10: =RANK(Daten!D10,Daten!D$2:D$101,0) -> 38 | E10: =RANK(Daten!E10,Daten!E$2:E$101,1) -> 79 | F10: =RANK(Daten!F10,Daten!F$2:F$101,1) -> 18 | G10: =RANK(Daten!G10,Daten!G$2:G$101,1) -> 47 | H10: =RANK(Daten!H10,Daten!H$2:H$101,0) -> 42 | I10: =RANK(Daten!I10,Daten!I$2:I$101,0) -> 70 | J10: =RANK(Daten!J10,Daten!J$2:J$101,0) -> 75 | K10: =RANK(Daten!K10,Daten!K$2:K$101,0) -> 37 | L10: =RANK(Daten!L10,Daten!L$2:L$101,0) -> 11 | M10: =RANK(Daten!M10,Daten!M$2:M$101,1) -> 37 | N10: =RANK(Daten!N10,Daten!N$2:N$101,0) -> 71 | O10: =RANK(Daten!O10,Daten!O$2:O$101,0) -> 54 | P10: =RANK(Daten!P10,Daten!P$2:P$101,0) -> 10 | Q10: =COUNTIF(B10:P10,"<=3") -> 0 | R10: =COUNTIF(B10:P10,1) -> 0
A11: =Daten!A11 -> Caleb Williams | B11: =RANK(Daten!B11,Daten!B$2:B$101,1) -> 80 | C11: =RANK(Daten!C11,Daten!C$2:C$101,0) -> 63 | D11: =RANK(Daten!D11,Daten!D$2:D$101,0) -> 64 | E11: =RANK(Daten!E11,Daten!E$2:E$101,1) -> 79 | F11: =RANK(Daten!F11,Daten!F$2:F$101,1) -> 1 | G11: =RANK(Daten!G11,Daten!G$2:G$101,1) -> 80 | H11: =RANK(Daten!H11,Daten!H$2:H$101,0) -> 63 | I11: =RANK(Daten!I11,Daten!I$2:I$101,0) -> 70 | J11: =RANK(Daten!J11,Daten!J$2:J$101,0) -> 75 | K11: =RANK(Daten!K11,Daten!K$2:K$101,0) -> 37 | L11: =RANK(Daten!L11,Daten!L$2:L$101,0) -> 30 | M11: =RANK(Daten!M11,Daten!M$2:M$101,1) -> 61 | N11: =RANK(Daten!N11,Daten!N$2:N$101,0) -> 68 | O11: =RANK(Daten!O11,Daten!O$2:O$101,0) -> 54 | P11: =RANK(Daten!P11,Daten!P$2:P$101,0) -> 12 | Q11: =COUNTIF(B11:P11,"<=3") -> 1 | R11: =COUNTIF(B11:P11,1) -> 1
A12: =Daten!A12 -> Jordan Love | B12: =RANK(Daten!B12,Daten!B$2:B$101,1) -> 38 | C12: =RANK(Daten!C12,Daten!C$2:C$101,0) -> 18 | D12: =RANK(Daten!D12,Daten!D$2:D$101,0) -> 53 | E12: =RANK(Daten!E12,Daten!E$2:E$101,1) -> 34 | F12: =RANK(Daten!F12,Daten!F$2:F$101,1) -> 71 | G12: =RANK(Daten!G12,Daten!G$2:G$101,1) -> 34 | H12: =RANK(Daten!H12,Daten!H$2:H$101,0) -> 42 | I12: =RANK(Daten!I12,Daten!I$2:I$101,0) -> 19 | J12: =RANK(Daten!J12,Daten!J$2:J$101,0) -> 75 | K12: =RANK(Daten!K12,Daten!K$2:K$101,0) -> 37 | L12: =RANK(Daten!L12,Daten!L$2:L$101,0) -> 30 | M12: =RANK(Daten!M12,Daten!M$2:M$101,1) -> 37 | N12: =RANK(Daten!N12,Daten!N$2:N$101,0) -> 2 | O12: =RANK(Daten!O12,Daten!O$2:O$101,0) -> 22 | P12: =RANK(Daten!P12,Daten!P$2:P$101,0) -> 19 | Q12: =COUNTIF(B12:P12,"<=3") -> 1 | R12: =COUNTIF(B12:P12,1) -> 0
A13: =Daten!A13 -> Brock Purdy | B13: =RANK(Daten!B13,Daten!B$2:B$101,1) -> 54 | C13: =RANK(Daten!C13,Daten!C$2:C$101,0) -> 63 | D13: =RANK(Daten!D13,Daten!D$2:D$101,0) -> 44 | E13: =RANK(Daten!E13,Daten!E$2:E$101,1) -> 55 | F13: =RANK(Daten!F13,Daten!F$2:F$101,1) -> 100 | G13: =RANK(Daten!G13,Daten!G$2:G$101,1) -> 77 | H13: =RANK(Daten!H13,Daten!H$2:H$101,0) -> 21 | I13: =RANK(Daten!I13,Daten!I$2:I$101,0) -> 42 | J13: =RANK(Daten!J13,Daten!J$2:J$101,0) -> 48 | K13: =RANK(Daten!K13,Daten!K$2:K$101,0) -> 37 | L13: =RANK(Daten!L13,Daten!L$2:L$101,0) -> 11 | M13: =RANK(Daten!M13,Daten!M$2:M$101,1) -> 45 | N13: =RANK(Daten!N13,Daten!N$2:N$101,0) -> 7 | O13: =RANK(Daten!O13,Daten!O$2:O$101,0) -> 2 | P13: =RANK(Daten!P13,Daten!P$2:P$101,0) -> 46 | Q13: =COUNTIF(B13:P13,"<=3") -> 1 | R13: =COUNTIF(B13:P13,1) -> 0
... A101: =Daten!A101 -> Brian Branch | B101: =RANK(Daten!B101,Daten!B$2:B$101,1) -> 81 | C101: =RANK(Daten!C101,Daten!C$2:C$101,0) -> 75 | D101: =RANK(Daten!D101,Daten!D$2:D$101,0) -> 89 | E101: =RANK(Daten!E101,Daten!E$2:E$101,1) -> 66 | F101: =RANK(Daten!F101,Daten!F$2:F$101,1) -> 81 | G101: =RANK(Daten!G101,Daten!G$2:G$101,1) -> 27 | H101: =RANK(Daten!H101,Daten!H$2:H$101,0) -> 42 | I101: =RANK(Daten!I101,Daten!I$2:I$101,0) -> 56 | J101: =RANK(Daten!J101,Daten!J$2:J$101,0) -> 48 | K101: =RANK(Daten!K101,Daten!K$2:K$101,0) -> 37 | L101: =RANK(Daten!L101,Daten!L$2:L$101,0) -> 30 | M101: =RANK(Daten!M101,Daten!M$2:M$101,1) -> 73 | N101: =RANK(Daten!N101,Daten!N$2:N$101,0) -> 99 | O101: =RANK(Daten!O101,Daten!O$2:O$101,0) -> 76 | P101: =RANK(Daten!P101,Daten!P$2:P$101,0) -> 82 | Q101: =COUNTIF(B101:P101,"<=3") -> 0 | R101: =COUNTIF(B101:P101,1) -> 0
A103: Einträge mit mind. 1 Top-3-Rang | B103: =COUNTIF(Q2:Q101,">0") -> 44
A104: Einträge ohne Top-3-Rang | B104: =COUNTIF(Q2:Q101,0) -> 56
A105: Verschiedene Nr. 1 (Einträge mit mind. 1 Rang 1) | B105: =COUNTIF(R2:R101,">0") -> 23
A107: Rang 1 = bester Wert in Spielrichtung (siehe Blatt Kategorien). Gleiche Werte = gleicher Rang. Formeln beziehen sich live auf das Datenblatt.

Sheet Kategorien
A1: # | B1: Kategorie | C1: Einheit | D1: Rang 1 = | E1: Wer gewinnt (Nr. 1) | F1: Datenqualität | G1: Mindestabstand im Spiel | H1: Zu nahe Paare | I1: Definition | J1: Quelle | K1: Hinweise | L1: Update-Plan
A2: 1 | B2: Geburtsdatum | C2: Datum | D2: ältester | E2: Matthew Stafford | F2: hart | G2: ≥ 90 Tage | H2: 86 | I2: Geburtsdatum laut NFL.com/Wikipedia. | J2: Wikipedia / NFL.com Spielerprofile | K2: Rang 1 = ältester Spieler (Stafford, 1988), Rang 100 = jüngster (Loveland, 2004). | L2: Nie (nur bei Kaderwechsel).
A3: 2 | B3: Grösse | C3: cm | D3: grösster | E3: Aidan Hutchinson | F3: mittel | G3: ≥ 2 cm | H3: 88 | I3: Körpergrösse laut NFL.com (Fuss/Zoll, auf cm gerundet). | J3: NFL.com / Wikipedia | K3: Viele Gleichstände bei 185/188/193 cm (Zoll-Raster) – Paar-Check beachten. Gewicht/BMI bewusst nicht kombiniert (Regel 8: nur Grösse + Gewicht). | L3: Nie.
A4: 3 | B4: Gewicht | C4: kg | D4: schwerster | E4: Dexter Lawrence | F4: mittel | G4: ≥ 2 kg | H4: 86 | I4: Kampfgewicht laut NFL.com (lbs, auf kg gerundet), Stand 2025. | J4: NFL.com / Wikipedia | K4: Mit O-Line/D-Line jetzt grosse Spreizung: D. Lawrence 154 kg bis DeVonta Smith 77 kg. | L4: Jährlich (Roster-Angaben).
A5: 4 | B5: Draft-Jahr | C5: Jahr | D5: frühestes (dienstältester) | E5: Matthew Stafford | F5: hart | G5: ≥ 1 Jahre | H5: 85 | I5: Jahr des NFL Drafts (= Profi seit). | J5: Wikipedia / PFR | K5: Viele Gleichstände (2020: 7 Spieler, 2024: 6) – als Runde nur mit Mindestabstand verwenden. | L5: Bei Kaderwechsel.
A6: 5 | B6: Draft-Position | C6: Overall-Pick | D6: frühester Pick (Nr. 1) | E6: Baker Mayfield, Bryce Young, Caleb Williams, Cam Ward, Fernando Mendoza, Jared Goff, Joe Burrow, Kyler Murray, Matthew Stafford, Myles Garrett, Trevor Lawrence | F6: hart | G6: ≥ 3 Positionen | H6: 81 | I6: Gesamtposition im NFL Draft. | J6: Wikipedia / PFR | K6: Drei Nr.-1-Picks (Goff 2016, Burrow 2020, Williams 2024) vs. Purdy Nr. 262 ('Mr. Irrelevant'). | L6: Nie.
A7: 6 | B7: Alter beim NFL-Debüt | C7: Jahre | D7: jüngstes Debüt | E7: Penei Sewell | F7: hart | G7: ≥ 0.25 Jahre | H7: 97 | I7: Alter am 1. September des Draftjahres (Saisonstart), aus Geburtsdatum und Draft-Jahr berechnet. | J7: Formel aus Geburtsdatum + Draft-Jahr | K7: Dezimalwert (2 Nachkommastellen) → praktisch keine Gleichstände. | L7: Nie.
A8: 7 | B8: Playoff-Spiele Karriere | C8: Spiele | D8: meiste | E8: Chris Jones | F8: mittel | G8: ≥ 1 Spiele | H8: 81 | I8: Playoff-Spiele im aktiven Kader (Wild Card bis Super Bowl), bis inkl. Super Bowl LX (Feb. 2026). | J8: PFR Spielerprofile (Playoffs), eigene Zählung | K8: Chris Jones 23 vor Mahomes 21 und Lane Johnson 17. Viele Nullen bei jungen Spielern – als Runde sparsam. Vor Livegang gegen PFR prüfen. | L8: Jährlich nach den Playoffs.
A9: 8 | B9: Saisons im aktuellen Team | C9: Saisons | D9: meiste | E9: Lane Johnson | F9: hart | G9: ≥ 1 Saisons | H9: 87 | I9: Referenzjahr minus erste Saison beim aktuellen Team plus 1 (Saison 2026 zählt). | J9: Formel aus Hilfsspalte 'Erste Saison beim Team' | K9: Mahomes/Kittle 10 Saisons. Gleichstände bei Draft-Jahrgängen unvermeidbar. | L9: Jährlich (Referenzjahr) und bei Wechsel.
A10: 9 | B10: Pro-Bowl-Nominierungen | C10: Anzahl | D10: meiste | E10: Trent Williams | F10: mittel | G10: ≥ 1 Nominierungen | H10: 91 | I10: Pro-Bowl-Nominierungen bis inkl. Saison 2024 (Original-Nominierungen, ohne Nachrücker-Zählweise-Unterschiede). | J10: Wikipedia / PFR | K10: Saison 2025 (Pro Bowl Games Feb. 2026) vor Livegang ergänzen – dann Beschriftung auf 'bis Saison 2025' ändern. | L10: Jährlich im Januar.
A11: 10 | B11: First-Team All-Pro | C11: Anzahl | D11: meiste | E11: Myles Garrett, T.J. Watt | F11: mittel | G11: ≥ 1 Auszeichnungen | H11: 95 | I11: AP First-Team All-Pro bis inkl. Saison 2024. | J11: Wikipedia / PFR | K11: Viele Nullen – sparsam einsetzen. Saison 2025 vor Livegang ergänzen (z. B. Smith-Njigba). | L11: Jährlich im Januar.
A12: 11 | B12: Super-Bowl-Teilnahmen | C12: Anzahl | D12: meiste | E12: Chris Jones, Patrick Mahomes | F12: hart | G12: ≥ 1 Teilnahmen | H12: 95 | I12: Super Bowls als Spieler im aktiven Kader, bis inkl. Super Bowl LX. | J12: Wikipedia / PFR | K12: Mahomes und Chris Jones 5. Mehrheit ohne Super Bowl – sparsam als Runde. | L12: Jährlich nach dem Super Bowl.
A13: 12 | B13: Rückennummer | C13: Nr. | D13: kleinste Nummer | E13: Roquan Smith | F13: hart | G13: ≥ 2 Nummern | H13: 84 | I13: Trikotnummer Saison 2026. | J13: Team-Roster / NFL.com | K13: Roquan Smith trägt die 0; mehrere Spieler die 1. Höchste Nummern: Crosby/J. Carter 98. Spielerisch: 'Wer hat die tiefste Nummer?' | L13: Jährlich.
... A16: 15 | B16: Einwohner Geburtsort | C16: Tsd. | D16: grösste Stadt | E16: Jalen Hurts, Jaylen Waddle | F16: mittel | G16: ≥ 10 % Unterschied | H16: 75 | I16: Einwohner der Geburtsstadt laut Wikipedia (US Census 2020/2023-Schätzung, auf Tausend gerundet); Barkley = Bezirk Bronx. | J16: Wikipedia Spielerprofil (Geburtsort) + Wikipedia Stadtartikel (Census) | K16: Analog 'Kantonseinwohner'. Hurts/Waddle (Houston) vorne; Hamilton in Griechenland geboren. Geburtsort ≠ Heimatstadt (z. B. Burrow Ames/Athens). Vor Livegang Stadtwerte gegen Census prüfen. | L16: Alle 2–3 Jahre.
A19: Hinweise
A20: Auswahl v2: 100 Spieler aller Positionen (26 QB, 13 RB, 27 WR, 7 TE, 7 OL, 12 DL/Edge, 2 LB, 5 CB, 3 S), alle gedraftet (Undrafted wie Brandon Aubrey/Jordan Mailata nicht enthalten, da Draft-Position fehlt). Teams Stand Sept. 2026 laut Kaderstand nach der Offseason 2026 (Wechsel vor Livegang prüfen).
A21: Spieler 33–100 wurden neu ergänzt; ihre Werte stammen aus Modellwissen (Stand Mitte 2026) und sind nicht einzeln gegen PFR/Spotrac geprüft – Einträge mit dem Vermerk 'prüfen' in der Anmerkung zuerst kontrollieren.
A22: Zeitbezug: Karriere-Auszeichnungen (Pro Bowl, All-Pro) bis inkl. Saison 2024 gesichert; Saison 2025 vor Livegang ergänzen und Beschriftung anpassen. Super Bowls bis LX. Verträge Stand Vertragsabschluss.
A23: Bewusst weggelassen: Karriere-Yards/-Touchdowns (nicht positionsübergreifend vergleichbar), Vertragsvolumen gesamt (korreliert mit Jahresgehalt), Madden-Rating (Regel 3), Instagram-Follower (zu volatil, nicht belegbar).
A24: Travis Kelce, Tyreek Hill und Aaron Rodgers nicht aufgenommen (Rücktritts-/Kaderstatus 2026 unsicher). Reserve-Kandidaten: Garrett Wilson, Nico Collins, DK Metcalf, Davante Adams, James Cook, Sam LaPorta.
A25: Mindestabstand: siehe Blatt 'Paar-Check'. Grösse und Draft-Jahr haben systembedingt viele Gleichstände.

Sheet Paar-Check
A1: Kategorie | B1: Spieler A | C1: Wert A | D1: Spieler B | E1: Wert B | F1: Differenz | G1: Gleichstand? | I1: Hinweis: bei Listen > 40 Einträgen werden nur benachbarte Paare in der Rangfolge geprüft (nicht alle Kombinationen).
A2: Geburtsdatum | B2: Dak Prescott | C2: 29.07.1993 | D2: Mike Evans | E2: 21.08.1993 | F2: 23 Tage
A3: Geburtsdatum | B3: Mike Evans | C3: 21.08.1993 | D3: George Kittle | E3: 09.10.1993 | F3: 49 Tage
A4: Geburtsdatum | B4: George Kittle | C4: 09.10.1993 | D4: Derrick Henry | E4: 04.01.1994 | F4: 87 Tage
A5: Geburtsdatum | B5: T.J. Watt | C5: 11.10.1994 | D5: Jared Goff | E5: 14.10.1994 | F5: 3 Tage
A6: Geburtsdatum | B6: Jared Goff | C6: 14.10.1994 | D6: Jalen Ramsey | E6: 24.10.1994 | F6: 10 Tage
A7: Geburtsdatum | B7: Terry McLaurin | C7: 15.09.1995 | D7: Patrick Mahomes | E7: 17.09.1995 | F7: 2 Tage
A8: Geburtsdatum | B8: Myles Garrett | C8: 29.12.1995 | D8: Quenton Nelson | E8: 19.03.1996 | F8: 81 Tage
A9: Geburtsdatum | B9: Quenton Nelson | C9: 19.03.1996 | D9: Josh Allen | E9: 21.05.1996 | F9: 63 Tage
A10: Geburtsdatum | B10: Josh Allen | C10: 21.05.1996 | D10: Christian McCaffrey | E10: 07.06.1996 | F10: 17 Tage
A11: Geburtsdatum | B11: Christian McCaffrey | C11: 07.06.1996 | D11: Derwin James | E11: 03.08.1996 | F11: 57 Tage
A12: Geburtsdatum | B12: Fred Warner | C12: 19.11.1996 | D12: Joe Burrow | E12: 10.12.1996 | F12: 21 Tage
A13: Geburtsdatum | B13: Joe Burrow | C13: 10.12.1996 | D13: Lamar Jackson | E13: 07.01.1997 | F13: 28 Tage
... A85: Geburtsdatum | B85: Travis Hunter | C85: 18.05.2003 | D85: Malik Nabers | E85: 28.07.2003 | F85: 71 Tage
A86: Geburtsdatum | B86: Malik Nabers | C86: 28.07.2003 | D86: Abdul Carter | E86: 28.07.2003 | F86: 0 Tage | G86: ja
A87: Geburtsdatum | B87: Fernando Mendoza | C87: 14.11.2003 | D87: Ashton Jeanty | E87: 02.12.2003 | F87: 18 Tage
A88: Grösse | B88: Jahmyr Gibbs | C88: 175 | D88: Kenneth Walker III | E88: 175 | F88: 0 | G88: ja
A89: Grösse | B89: Kenneth Walker III | C89: 175 | D89: Kyren Williams | E89: 175 | F89: 0 | G89: ja
A90: Grösse | B90: Kyren Williams | C90: 175 | D90: De'Von Achane | E90: 175 | F90: 0 | G90: ja
A91: Grösse | B91: De'Von Achane | C91: 175 | D91: Zay Flowers | E91: 175 | F91: 0 | G91: ja
A92: Grösse | B92: Kyler Murray | C92: 178 | D92: Bryce Young | E92: 178 | F92: 0 | G92: ja
A93: Grösse | B93: Bryce Young | C93: 178 | D93: Josh Jacobs | E93: 178 | F93: 0 | G93: ja
A94: Grösse | B94: Josh Jacobs | C94: 178 | D94: Jonathan Taylor | E94: 178 | F94: 0 | G94: ja
A95: Grösse | B95: Jonathan Taylor | C95: 178 | D95: TreVeyon Henderson | E95: 178 | F95: 0 | G95: ja
A96: Grösse | B96: TreVeyon Henderson | C96: 178 | D96: Jaylen Waddle | E96: 178 | F96: 0 | G96: ja
A97: Grösse | B97: Christian McCaffrey | C97: 180 | D97: Bijan Robinson | E97: 180 | F97: 0 | G97: ja
A98: Grösse | B98: Bijan Robinson | C98: 180 | D98: James Cook | E98: 180 | F98: 0 | G98: ja
A99: Grösse | B99: Saquon Barkley | C99: 183 | D99: Ja'Marr Chase | E99: 183 | F99: 0 | G99: ja
... A177: Gewicht | B177: Jaylen Waddle | C177: 83 | D177: Zay Flowers | E177: 83 | F177: 0 | G177: ja
A178: Gewicht | B178: Zay Flowers | C178: 83 | D178: Ladd McConkey | E178: 84 | F178: 1
A179: Gewicht | B179: Ladd McConkey | C179: 84 | D179: Travis Hunter | E179: 84 | F179: 0 | G179: ja
A180: Gewicht | B180: Travis Hunter | C180: 84 | D180: Devon Witherspoon | E180: 84 | F180: 0 | G180: ja
A181: Gewicht | B181: Devon Witherspoon | C181: 84 | D181: De'Von Achane | E181: 85 | F181: 1
A182: Gewicht | B182: De'Von Achane | C182: 85 | D182: James Cook | E182: 86 | F182: 1
A183: Gewicht | B183: James Cook | C183: 86 | D183: Sauce Gardner | E183: 86 | F183: 0 | G183: ja
A184: Gewicht | B184: Sauce Gardner | C184: 86 | D184: Derek Stingley Jr. | E184: 86 | F184: 0 | G184: ja
A185: Gewicht | B185: Derek Stingley Jr. | C185: 86 | D185: Brian Branch | E185: 86 | F185: 0 | G185: ja
A186: Gewicht | B186: Justin Jefferson | C186: 88 | D186: Jaxon Smith-Njigba | E186: 89 | F186: 1
A187: Gewicht | B187: Jaxon Smith-Njigba | C187: 89 | D187: Jahmyr Gibbs | E187: 90 | F187: 1
A188: Gewicht | B188: Jahmyr Gibbs | C188: 90 | D188: CeeDee Lamb | E188: 91 | F188: 1
...
