Workbook

Sheet World Records
A1: ID | B1: Type | C1: Category | D1: Record | E1: Holder | F1: Nationality | G1: Gender | H1: Value | I1: Unit | J1: Display | K1: Year set | L1: Years standing | M1: Record body | N1: Check | O1: Note
A2: 1 | B2: Pro sport | C2: Athletics | D2: 100 m (men) | E2: Usain Bolt | F2: JAM | G2: M | H2: 9.58 | I2: s | J2: 9.58 | K2: 2009 | L2: ='Notes & Sources'!$B$3-K2 -> 17 | M2: World Athletics | N2: Long-standing record
A3: 2 | B3: Pro sport | C3: Athletics | D3: 200 m (men) | E3: Usain Bolt | F3: JAM | G3: M | H3: 19.19 | I3: s | J3: 19.19 | K3: 2009 | L3: ='Notes & Sources'!$B$3-K3 -> 17 | M3: World Athletics | N3: Long-standing record
A4: 3 | B4: Pro sport | C4: Athletics | D4: 400 m (men) | E4: Wayde van Niekerk | F4: RSA | G4: M | H4: 43.03 | I4: s | J4: 43.03 | K4: 2016 | L4: ='Notes & Sources'!$B$3-K4 -> 10 | M4: World Athletics | N4: Long-standing record
A5: 4 | B5: Pro sport | C5: Athletics | D5: 800 m (men) | E5: David Rudisha | F5: KEN | G5: M | H5: 100.91 | I5: s | J5: 1:40.91 | K5: 2012 | L5: ='Notes & Sources'!$B$3-K5 -> 14 | M5: World Athletics | N5: Long-standing record
A6: 5 | B6: Pro sport | C6: Athletics | D6: Mile (men) | E6: Hicham El Guerrouj | F6: MAR | G6: M | H6: 223.13 | I6: s | J6: 3:43.13 | K6: 1999 | L6: ='Notes & Sources'!$B$3-K6 -> 27 | M6: World Athletics | N6: Long-standing record
A7: 6 | B7: Pro sport | C7: Athletics | D7: 10,000 m (men) | E7: Joshua Cheptegei | F7: UGA | G7: M | H7: 1571 | I7: s | J7: 26:11.00 | K7: 2020 | L7: ='Notes & Sources'!$B$3-K7 -> 6 | M7: World Athletics | N7: Long-standing record
A8: 7 | B8: Pro sport | C8: Athletics | D8: Marathon (men) | E8: Sabastian Sawe | F8: KEN | G8: M | H8: 7170 | I8: s | J8: 1:59:30 | K8: 2026 | L8: ='Notes & Sources'!$B$3-K8 -> 0 | M8: World Athletics | N8: Checked online Sept 2026 | O8: First official sub-2h marathon, London
A9: 8 | B9: Pro sport | C9: Athletics | D9: Marathon (women-only race) | E9: Tigst Assefa | F9: ETH | G9: W | H9: 8141 | I9: s | J9: 2:15:41 | K9: 2026 | L9: ='Notes & Sources'!$B$3-K9 -> 0 | M9: World Athletics | N9: Checked online Sept 2026 | O9: London 2026
A10: 9 | B10: Pro sport | C10: Athletics | D10: 110 m hurdles (men) | E10: Aries Merritt | F10: USA | G10: M | H10: 12.8 | I10: s | J10: 12.80 | K10: 2012 | L10: ='Notes & Sources'!$B$3-K10 -> 14 | M10: World Athletics | N10: Long-standing record
A11: 10 | B11: Pro sport | C11: Athletics | D11: 400 m hurdles (men) | E11: Karsten Warholm | F11: NOR | G11: M | H11: 45.94 | I11: s | J11: 45.94 | K11: 2021 | L11: ='Notes & Sources'!$B$3-K11 -> 5 | M11: World Athletics | N11: Long-standing record
A12: 11 | B12: Pro sport | C12: Athletics | D12: High jump (men) | E12: Javier Sotomayor | F12: CUB | G12: M | H12: 2.45 | I12: m | J12: 2.45 m | K12: 1993 | L12: ='Notes & Sources'!$B$3-K12 -> 33 | M12: World Athletics | N12: Long-standing record
A13: 12 | B13: Pro sport | C13: Athletics | D13: Pole vault (men) | E13: Armand Duplantis | F13: SWE | G13: M | H13: 6.31 | I13: m | J13: 6.31 m | K13: 2026 | L13: ='Notes & Sources'!$B$3-K13 -> 0 | M13: World Athletics | N13: Checked online Sept 2026 | O13: His 15th world record
A14: 13 | B14: Pro sport | C14: Athletics | D14: Long jump (men) | E14: Mike Powell | F14: USA | G14: M | H14: 8.95 | I14: m | J14: 8.95 m | K14: 1991 | L14: ='Notes & Sources'!$B$3-K14 -> 35 | M14: World Athletics | N14: Long-standing record
A15: 14 | B15: Pro sport | C15: Athletics | D15: Javelin (men) | E15: Jan Železný | F15: CZE | G15: M | H15: 98.48 | I15: m | J15: 98.48 m | K15: 1996 | L15: ='Notes & Sources'!$B$3-K15 -> 30 | M15: World Athletics | N15: Long-standing record
A16: 15 | B16: Pro sport | C16: Athletics | D16: Decathlon | E16: Kevin Mayer | F16: FRA | G16: M | H16: 9126 | I16: points | J16: 9126 pts | K16: 2018 | L16: ='Notes & Sources'!$B$3-K16 -> 8 | M16: World Athletics | N16: Long-standing record
A17: 16 | B17: Pro sport | C17: Athletics | D17: Indoor heptathlon | E17: Simon Ehammer | F17: SUI | G17: M | H17: 6670 | I17: points | J17: 6670 pts | K17: 2026 | L17: ='Notes & Sources'!$B$3-K17 -> 0 | M17: World Athletics | N17: Checked online Sept 2026 | O17: Beat Ashton Eaton's 2012 record
A18: 17 | B18: Pro sport | C18: Athletics | D18: 100 m (women) | E18: Florence Griffith-Joyner | F18: USA | G18: W | H18: 10.49 | I18: s | J18: 10.49 | K18: 1988 | L18: ='Notes & Sources'!$B$3-K18 -> 38 | M18: World Athletics | N18: Long-standing record
A19: 18 | B19: Pro sport | C19: Athletics | D19: 200 m (women) | E19: Florence Griffith-Joyner | F19: USA | G19: W | H19: 21.34 | I19: s | J19: 21.34 | K19: 1988 | L19: ='Notes & Sources'!$B$3-K19 -> 38 | M19: World Athletics | N19: Long-standing record
A20: 19 | B20: Pro sport | C20: Athletics | D20: 400 m (women) | E20: Marita Koch | F20: GDR | G20: W | H20: 47.6 | I20: s | J20: 47.60 | K20: 1985 | L20: ='Notes & Sources'!$B$3-K20 -> 41 | M20: World Athletics | N20: Long-standing record
A21: 20 | B21: Pro sport | C21: Athletics | D21: 800 m (women) | E21: Jarmila Kratochvílová | F21: TCH | G21: W | H21: 113.28 | I21: s | J21: 1:53.28 | K21: 1983 | L21: ='Notes & Sources'!$B$3-K21 -> 43 | M21: World Athletics | N21: Long-standing record | O21: Oldest individual athletics WR
A22: 21 | B22: Pro sport | C22: Athletics | D22: Pole vault (women) | E22: Yelena Isinbayeva | F22: RUS | G22: W | H22: 5.06 | I22: m | J22: 5.06 m | K22: 2009 | L22: ='Notes & Sources'!$B$3-K22 -> 17 | M22: World Athletics | N22: Long-standing record
A23: 22 | B23: Pro sport | C23: Athletics | D23: Javelin (women) | E23: Barbora Špotáková | F23: CZE | G23: W | H23: 72.28 | I23: m | J23: 72.28 m | K23: 2008 | L23: ='Notes & Sources'!$B$3-K23 -> 18 | M23: World Athletics | N23: Long-standing record
A24: 23 | B24: Pro sport | C24: Swimming | D24: 200 m freestyle (men) | E24: Paul Biedermann | F24: GER | G24: M | H24: 102 | I24: s | J24: 1:42.00 | K24: 2009 | L24: ='Notes & Sources'!$B$3-K24 -> 17 | M24: World Aquatics | N24: Checked online Sept 2026 | O24: Super-suit era
A25: 24 | B25: Pro sport | C25: Swimming | D25: 800 m freestyle (men) | E25: Zhang Lin | F25: CHN | G25: M | H25: 452.12 | I25: s | J25: 7:32.12 | K25: 2009 | L25: ='Notes & Sources'!$B$3-K25 -> 17 | M25: World Aquatics | N25: Checked online Sept 2026 | O25: Super-suit era
A26: 25 | B26: Pro sport | C26: Olympics | D26: Most Olympic medals | E26: Michael Phelps | F26: USA | G26: M | H26: 28 | I26: medals | J26: 28 | K26: 2016 | L26: ='Notes & Sources'!$B$3-K26 -> 10 | M26: IOC | N26: Long-standing record
A27: 26 | B27: Pro sport | C27: Olympics | D27: Most Olympic gold medals | E27: Michael Phelps | F27: USA | G27: M | H27: 23 | I27: golds | J27: 23 | K27: 2016 | L27: ='Notes & Sources'!$B$3-K27 -> 10 | M27: IOC | N27: Long-standing record
A28: 27 | B28: Pro sport | C28: Olympics | D28: Most golds at one Summer Games | E28: Michael Phelps | F28: USA | G28: M | H28: 8 | I28: golds | J28: 8 | K28: 2008 | L28: ='Notes & Sources'!$B$3-K28 -> 18 | M28: IOC | N28: Long-standing record | O28: Beijing 2008
A29: 28 | B29: Pro sport | C29: Olympics | D29: Most Olympic medals (woman) | E29: Larisa Latynina | F29: URS | G29: W | H29: 18 | I29: medals | J29: 18 | K29: 1964 | L29: ='Notes & Sources'!$B$3-K29 -> 62 | M29: IOC | N29: Long-standing record
A30: 29 | B30: Pro sport | C30: Olympics | D30: Most Winter Olympic gold medals | E30: Johannes Høsflot Klæbo | F30: NOR | G30: M | H30: 11 | I30: golds | J30: 11 | K30: 2026 | L30: ='Notes & Sources'!$B$3-K30 -> 0 | M30: IOC | N30: Checked online Sept 2026
A31: 30 | B31: Pro sport | C31: Olympics | D31: Most golds at one Winter Games | E31: Johannes Høsflot Klæbo | F31: NOR | G31: M | H31: 6 | I31: golds | J31: 6 | K31: 2026 | L31: ='Notes & Sources'!$B$3-K31 -> 0 | M31: IOC | N31: Checked online Sept 2026 | O31: Won all 6 cross-country events
A32: 31 | B32: Pro sport | C32: Olympics | D32: Most Paralympic medals | E32: Trischa Zorn | F32: USA | G32: W | H32: 55 | I32: medals | J32: 55 | K32: 2004 | L32: ='Notes & Sources'!$B$3-K32 -> 22 | M32: IPC | N32: Long-standing record | O32: 41 of them gold
A33: 32 | B33: Pro sport | C33: Football | D33: Most World Cup goals (career) | E33: Kylian Mbappé | F33: FRA | G33: M | H33: 22 | I33: goals | J33: 22 | K33: 2026 | L33: ='Notes & Sources'!$B$3-K33 -> 0 | M33: FIFA | N33: Checked online Sept 2026 | O33: Passed Messi (21) and Klose (16) in 2026
A34: 33 | B34: Pro sport | C34: Football | D34: Most World Cup matches played | E34: Lionel Messi | F34: ARG | G34: M | H34: 34 | I34: matches | J34: 34 | K34: 2026 | L34: ='Notes & Sources'!$B$3-K34 -> 0 | M34: FIFA | N34: Checked online Sept 2026
A35: 34 | B35: Pro sport | C35: Football | D35: Most goals at a single World Cup | E35: Just Fontaine | F35: FRA | G35: M | H35: 13 | I35: goals | J35: 13 | K35: 1958 | L35: ='Notes & Sources'!$B$3-K35 -> 68 | M35: FIFA | N35: Checked online Sept 2026 | O35: Mbappé got 10 in 2026
A36: 35 | B36: Pro sport | C36: Football | D36: Most World Cup titles | E36: Brazil | F36: BRA | G36: Team | H36: 5 | I36: titles | J36: 5 | K36: 2002 | L36: ='Notes & Sources'!$B$3-K36 -> 24 | M36: FIFA | N36: Checked online Sept 2026 | O36: Spain won 2026 (their 2nd)
A37: 36 | B37: Pro sport | C37: Football | D37: Most Women's World Cup goals | E37: Marta | F37: BRA | G37: W | H37: 17 | I37: goals | J37: 17 | K37: 2019 | L37: ='Notes & Sources'!$B$3-K37 -> 7 | M37: FIFA | N37: Long-standing record
A38: 37 | B38: Pro sport | C38: Football | D38: Most goals in one international match | E38: Archie Thompson | F38: AUS | G38: M | H38: 13 | I38: goals | J38: 13 | K38: 2001 | L38: ='Notes & Sources'!$B$3-K38 -> 25 | M38: FIFA | N38: Long-standing record | O38: vs American Samoa
A39: 38 | B39: Pro sport | C39: Football | D39: Biggest international win (margin) | E39: Australia | F39: AUS | G39: Team | H39: 31 | I39: goals | J39: 31–0 | K39: 2001 | L39: ='Notes & Sources'!$B$3-K39 -> 25 | M39: FIFA | N39: Long-standing record | O39: vs American Samoa
A40: 39 | B40: Pro sport | C40: Football | D40: Highest football attendance | E40: Uruguay v Brazil, Maracanã | F40: BRA | G40: Team | H40: 173850 | I40: spectators | J40: 173,850 | K40: 1950 | L40: ='Notes & Sources'!$B$3-K40 -> 76 | M40: FIFA | N40: Long-standing record | O40: Official figure
...

Sheet By Category
A1: Type | B1: Category | C1: Records | D1: Oldest (year set) | E1: Newest (year set)
A2: Pro sport | B2: Athletics | C2: =COUNTIFS('World Records'!B:B,A2,'World Records'!C:C,B2) -> 22 | D2: =_xlfn.MINIFS('World Records'!K:K,'World Records'!B:B,A2,'World Records'!C:C,B2) -> 1983 | E2: =_xlfn.MAXIFS('World Records'!K:K,'World Records'!B:B,A2,'World Records'!C:C,B2) -> 2026
A3: Pro sport | B3: Swimming | C3: =COUNTIFS('World Records'!B:B,A3,'World Records'!C:C,B3) -> 2 | D3: =_xlfn.MINIFS('World Records'!K:K,'World Records'!B:B,A3,'World Records'!C:C,B3) -> 2009 | E3: =_xlfn.MAXIFS('World Records'!K:K,'World Records'!B:B,A3,'World Records'!C:C,B3) -> 2009
A4: Pro sport | B4: Olympics | C4: =COUNTIFS('World Records'!B:B,A4,'World Records'!C:C,B4) -> 7 | D4: =_xlfn.MINIFS('World Records'!K:K,'World Records'!B:B,A4,'World Records'!C:C,B4) -> 1964 | E4: =_xlfn.MAXIFS('World Records'!K:K,'World Records'!B:B,A4,'World Records'!C:C,B4) -> 2026
A5: Pro sport | B5: Football | C5: =COUNTIFS('World Records'!B:B,A5,'World Records'!C:C,B5) -> 18 | D5: =_xlfn.MINIFS('World Records'!K:K,'World Records'!B:B,A5,'World Records'!C:C,B5) -> 1950 | E5: =_xlfn.MAXIFS('World Records'!K:K,'World Records'!B:B,A5,'World Records'!C:C,B5) -> 2026
A6: Pro sport | B6: Basketball | C6: =COUNTIFS('World Records'!B:B,A6,'World Records'!C:C,B6) -> 7 | D6: =_xlfn.MINIFS('World Records'!K:K,'World Records'!B:B,A6,'World Records'!C:C,B6) -> 1960 | E6: =_xlfn.MAXIFS('World Records'!K:K,'World Records'!B:B,A6,'World Records'!C:C,B6) -> 2016
A7: Pro sport | B7: American football | C7: =COUNTIFS('World Records'!B:B,A7,'World Records'!C:C,B7) -> 6 | D7: =_xlfn.MINIFS('World Records'!K:K,'World Records'!B:B,A7,'World Records'!C:C,B7) -> 1972 | E7: =_xlfn.MAXIFS('World Records'!K:K,'World Records'!B:B,A7,'World Records'!C:C,B7) -> 2023
A8: Pro sport | B8: Ice hockey | C8: =COUNTIFS('World Records'!B:B,A8,'World Records'!C:C,B8) -> 5 | D8: =_xlfn.MINIFS('World Records'!K:K,'World Records'!B:B,A8,'World Records'!C:C,B8) -> 1920 | E8: =_xlfn.MAXIFS('World Records'!K:K,'World Records'!B:B,A8,'World Records'!C:C,B8) -> 1999
A9: Pro sport | B9: Tennis | C9: =COUNTIFS('World Records'!B:B,A9,'World Records'!C:C,B9) -> 4 | D9: =_xlfn.MINIFS('World Records'!K:K,'World Records'!B:B,A9,'World Records'!C:C,B9) -> 1973 | E9: =_xlfn.MAXIFS('World Records'!K:K,'World Records'!B:B,A9,'World Records'!C:C,B9) -> 2024
A10: Pro sport | B10: Golf | C10: =COUNTIFS('World Records'!B:B,A10,'World Records'!C:C,B10) -> 2 | D10: =_xlfn.MINIFS('World Records'!K:K,'World Records'!B:B,A10,'World Records'!C:C,B10) -> 1986 | E10: =_xlfn.MAXIFS('World Records'!K:K,'World Records'!B:B,A10,'World Records'!C:C,B10) -> 2016
A11: Pro sport | B11: Cricket | C11: =COUNTIFS('World Records'!B:B,A11,'World Records'!C:C,B11) -> 3 | D11: =_xlfn.MINIFS('World Records'!K:K,'World Records'!B:B,A11,'World Records'!C:C,B11) -> 1948 | E11: =_xlfn.MAXIFS('World Records'!K:K,'World Records'!B:B,A11,'World Records'!C:C,B11) -> 2010
A12: Pro sport | B12: Motorsport | C12: =COUNTIFS('World Records'!B:B,A12,'World Records'!C:C,B12) -> 5 | D12: =_xlfn.MINIFS('World Records'!K:K,'World Records'!B:B,A12,'World Records'!C:C,B12) -> 1976 | E12: =_xlfn.MAXIFS('World Records'!K:K,'World Records'!B:B,A12,'World Records'!C:C,B12) -> 2023
A13: Pro sport | B13: Winter sports | C13: =COUNTIFS('World Records'!B:B,A13,'World Records'!C:C,B13) -> 3 | D13: =_xlfn.MINIFS('World Records'!K:K,'World Records'!B:B,A13,'World Records'!C:C,B13) -> 1989 | E13: =_xlfn.MAXIFS('World Records'!K:K,'World Records'!B:B,A13,'World Records'!C:C,B13) -> 2017
... A26: Crazy record | B26: Crazy distance | C26: =COUNTIFS('World Records'!B:B,A26,'World Records'!C:C,B26) -> 3 | D26: =_xlfn.MINIFS('World Records'!K:K,'World Records'!B:B,A26,'World Records'!C:C,B26) -> 1974 | E26: =_xlfn.MAXIFS('World Records'!K:K,'World Records'!B:B,A26,'World Records'!C:C,B26) -> 2002
A27: Pro sport | B27: Total | C27: =COUNTIF('World Records'!B:B,A27) -> 95
A28: Crazy record | B28: Total | C28: =COUNTIF('World Records'!B:B,A28) -> 83
A29: All | B29: Total | C29: =C27+C28 -> 178

Sheet Notes & Sources
A1: Sportrankle – Sports World Records (state: September 2026)
A3: Reference year (edit) | B3: 2026
A5: Type | B5: 'Pro sport' = official records from federations and leagues. 'Crazy record' = Guinness titles and bizarre historic facts.
A6: Value | B6: Numeric value for sorting. Times are stored in seconds (see 'Display' for the readable version), speeds in km/h, ages in years.
A7: Years standing | B7: Reference year minus Year set. Change B3 to update.
A8: Check: Checked online Sept 2026 | B8: Current holder and value confirmed against Guinness World Records, World Athletics, FIFA/UEFA or major news reports on 25 Sept 2026.
A9: Check: Long-standing record | B9: Historic records that stood for years and had no known change as of Sept 2026. Records that could plausibly have changed recently were left out rather than guessed.
A10: Left out on purpose | B10: Records of active athletes that move every week (Ronaldo's international goals, LeBron's points, Ovechkin's goals etc.) and records set in the busy summer 2026 swimming/athletics season that couldn't be confirmed.
A11: Comparability | B11: Units differ between rows – rank within the same unit, or use 'Year set' / 'Years standing' to rank across all records.
